Workbook
Name lm: #REF!

Sheet Regulamento
B2: REGULAMENTO
B4: - O Bolão será composto apenas pelos jogos da 1ª fase da copa do mundo
C5: O Palpite contemplará todos os jogos da 1º fase e a indicação dos 4 primeiros colocados da Copa do Mundo (em ordem definida), das duas seleções classificadas por grupo e do artilheiro da competição
C8: Uma vez entregue a planilha, não será permitida a revisão dos palpites
B10: PREMIOS: 1o - 70% - 2o - 20% 3o - 10%
B12: - O valor das apostas será de R$100,00 (cem reais)
B13: - Um mesmo apostador poderá fazer quantas apostas quiser, pagando 100 reais por cada uma.
B14: - O pagamento deverá ser feito em dinheiro diretamente para o Rodrigo Amorim por PIX para CPF: 41670531104
B15: - Após o pagamento envie comprovante para receber acesso a planilha de palpites
B16: - Sempre que possível serão enviados resultados parciais para acompanhamento dos participantes
B17: - Será confeccionada uma planilha com os resultados de todos os participantes para acompanhamento da disputa.
C18: A planilha será enviada para o e-mail preenchido na planilha de palpite até o dia 18/11/2022
B20: - Não há critério de desempate. Em caso de empate, o prêmio será dividido.
C21: Exemplo: Se os apostadores A e B empatarem em primeiro com 305 pontos e o apostador C ficar logo a seguir, sozinho, com 302, os prêmios de primeiro e segundo lugares serão somados e divididos entre A e B e o prêmio de terceiro será pago a C.
C23: As apostas só serão válidas se o pagamento for comprovado até o dia 18/11/2022
B27: PONTUAÇÃO
B29: JOGOS
B31: Acertar o placar do jogo e o vencedor - 10 pts | I31: 1
B32: Ex: Brasil 2x1 Japão (pallpite); Brasil 2x1 Japão (Resultado)
B34: Acertar o empate com nº gols certos - 10 pts | I34: 2
B35: Ex: Brasil 0x0 Japão (palpite); Brasil 0x0 Japão (Resultado)
B37: Acertar o vencedor e a diferença de gols - 6 pts | I37: 3
B38: Ex: Brasil 1x0 Japão (pallpite); Brasil 2x1 Japão (Resultado)
B40: Acertar o empate com o nº gols errado, diferença de 1 gol - 6 pts
B41: Ex: Brasil 1x1 Japão (palpite); Brasil 0x0 Japão (Resultado)
B43: Somente acertar o vencedor - 3 pts | I43: 5
B44: Ex: Brasil 1x0 Japão (pallpite); Brasil 3x0 Japão (Resultado)
B46: Acertar o empate com o nº gols errado, diferença maior do que 1 gol - 3 pts
B47: Ex: Brasil 1x1 Japão (pallpite); Brasil 3x3 Japão (Resultado)
B50: OS QUATRO PRIMEIROS DO CAMPEONATO
B52: - Cada participante apostará no Campeão, no Vice, no 3º e no 4º colocados.
B54: Acertar uma das 4 seleções na posição errada - 20 pts
B55: Ex: Brasil Campeão (palpite); Brasil 3º lugar (resultado) // Argentina 4º (palpite); Argentina Vice-campeão (resultado)
B57: Acertar na posição correta
B58: CAMPEÃO - + 20 pts = 40 pts
B59: VICE-CAMPEÃO - + 15 pts = 35 pts
B60: 3º - + 10 pts = 30 pts
B61: 4º - + 5 pts = 25 pts
... B78: 3º Colocado Geral = 10% do total arrecadado

Sheet Resultado Oficial
LN1: Grupo A
A2: Bolão Copa 2022 - Câmara dos Lordes - Resultados Oficiais | LM2: Seleção | LN2: PT | LO2: J | LP2: V | LQ2: E | LR2: D | LS2: GP | LT2: GC | LU2: SG
LM3: Catar | LN3: =IF(OR(E20="",G20=""),0,IF(LO3=0,0,IF(E20>G20,3,IF(E20=G20,1,0)))+IF(OR(E22="",G22=""),0,IF(E22>G22,3,IF(E22=G22,1,0)))+IF(OR(G25="",E25=""),0,IF(G25>E25,3,IF(G25=E25,1,0)))) -> 0 | LO3: =IF(AND(E20<>"",G20<>""),1,0)+IF(AND(E22<>"",G22<>""),1,0)+IF(AND(E25<>"",G25<>""),1,0) -> 3 | LP3: =IF(OR(E20="",G20=""),0,IF(E20>G20,1,0))+IF(OR(E22="",G22=""),0,IF(E22>G22,1,0))+IF(OR(G25="",E25=""),0,IF(G25>E25,1,0)) -> 0 | LQ3: =IF(OR(E20="",G20=""),0,IF(E20=G20,1,0))+IF(OR(E22="",G22=""),0,IF(E22=G22,1,0))+IF(OR(G25="",E25=""),0,IF(G25=E25,1,0)) -> 0 | LR3: =IF(OR(E20="",G20=""),0,IF(E20<G20,1,0))+IF(OR(E22="",G22=""),0,IF(E22<G22,1,0))+IF(OR(G25="",E25=""),0,IF(G25<E25,1,0)) -> 3 | LS3: =E20+E22+G25 -> 1 | LT3: =G20+G22+E25 -> 7 | LU3: =LS3-LT3 -> -6 | LV3: =LN3 -> 0 | LW3: =LU3/10 -> -0.6 | LX3: =LS3/100 -> 0.01 | LY3: =SUM(LV3:LX3) -> -0.59 | LZ3: =IF(LY3=LY4,IF(E20>G20,0.001,0),0) -> 0 | MA3: =IF(LY3=LY5,IF(E22>G22,0.001,0),0) -> 0 | MB3: =IF(LY3=LY6,IF(G25>E25,0.001,0),0) -> 0 | MC3: =SUM(LY3:MB3) -> -0.59 | MD3: =RANK(MC3,$MC$3:$MC$6,0) -> 4 | ME3: =MD3 -> 4 | MF3: 1 | MG3: =MATCH(MF3,$ME$3:$ME$6,0) -> 4 | MH3: =INDEX($LM$3:$LM$6,MG3) -> Holanda
LM4: Equador | LN4: =IF(OR(G20="",E20=""),0,IF(LO4=0,0,IF(G20>E20,3,IF(G20=E20,1,0)))+IF(OR(G23="",E23=""),0,IF(G23>E23,3,IF(G23=E23,1,0)))+IF(OR(G24="",E24=""),0,IF(E24>G24,3,IF(E24=G24,1,0)))) -> 4 | LO4: =IF(AND(E20<>"",G20<>""),1,0)+IF(AND(E23<>"",G23<>""),1,0)+IF(AND(E25<>"",G25<>""),1,0) -> 3 | LP4: =IF(OR(G20="",E20=""),0,IF(G20>E20,1,0))+IF(OR(G23="",E23=""),0,IF(G23>E23,1,0))+IF(OR(E25="",G25=""),0,IF(E25>G25,1,0)) -> 2 | LQ4: =IF(OR(G20="",E20=""),0,IF(G20=E20,1,0))+IF(OR(G23="",E23=""),0,IF(G23=E23,1,0))+IF(OR(E25="",G25=""),0,IF(E25=G25,1,0)) -> 1 | LR4: =IF(OR(G20="",E20=""),0,IF(G20<E20,1,0))+IF(OR(G23="",E23=""),0,IF(G23<E23,1,0))+IF(OR(E25="",G25=""),0,IF(E25<G25,1,0)) -> 0 | LS4: =G20+G23+E25 -> 5 | LT4: =E20+E23+G25 -> 1 | LU4: =LS4-LT4 -> 4 | LV4: =LN4 -> 4 | LW4: =LU4/10 -> 0.4 | LX4: =LS4/100 -> 0.05 | LY4: =SUM(LV4:LX4) -> 4.45 | LZ4: =IF(LY4=LY3,IF(G20>E20,0.001,0),0) -> 0 | MA4: =IF(LY4=LY5,IF(E24>G24,0.001,0),0) -> 0 | MB4: =IF(LY4=LY6,IF(G23>E23,0.001,0),0) -> 0 | MC4: =SUM(LY4:MB4) -> 4.45 | MD4: =RANK(MC4,$MC$3:$MC$6,0) -> 3 | ME4: =IF(OR(AND(MD3=MD4,MD3=MD5,MD3=MD6),AND(MD4=MD3,MD4=MD5),AND(MD4=MD3,MD4=MD6),MD4=MD3),MD4+1,MD4) -> 3 | MF4: 2 | MG4: =MATCH(MF4,$ME$3:$ME$6,0) -> 3 | MH4: =INDEX($LM$3:$LM$6,MG4) -> Senegal
LM5: Senegal | LN5: =IF(OR(E21="",G21=""),0,IF(LO5=0,0,IF(E21>G21,3,IF(E21=G21,1,0)))+IF(OR(G22="",E22=""),0,IF(G22>E22,3,IF(G22=E22,1,0)))+IF(OR(G24="",E24=""),0,IF(G24>E24,3,IF(E24=G24,1,0)))) -> 6 | LO5: =IF(AND(E21<>"",G21<>""),1,0)+IF(AND(E22<>"",G22<>""),1,0)+IF(AND(E24<>"",G24<>""),1,0) -> 3 | LP5: =IF(OR(E21="",G21=""),0,IF(E21>G21,1,0))+IF(OR(G22="",E22=""),0,IF(G22>E22,1,0))+IF(OR(G24="",E24=""),0,IF(G24>E24,1,0)) -> 2 | LQ5: =IF(OR(E21="",G21=""),0,IF(E21=G21,1,0))+IF(OR(G22="",E22=""),0,IF(G22=E22,1,0))+IF(OR(G24="",E24=""),0,IF(G24=E24,1,0)) -> 0 | LR5: =IF(OR(E21="",G21=""),0,IF(E21<G21,1,0))+IF(OR(G22="",E22=""),0,IF(G22<E22,1,0))+IF(OR(G24="",E24=""),0,IF(G24<E24,1,0)) -> 1 | LS5: =E21+G22+G24 -> 5 | LT5: =G21+E22+E24 -> 4 | LU5: =LS5-LT5 -> 1 | LV5: =LN5 -> 6 | LW5: =LU5/10 -> 0.1 | LX5: =LS5/100 -> 0.05 | LY5: =SUM(LV5:LX5) -> 6.15 | LZ5: =IF(LY5=LY3,IF(G22>E22,0.001,0),0) -> 0 | MA5: =IF(LY5=LY4,IF(G24>E24,0.001,0),0) -> 0 | MB5: =IF(LY5=LY6,IF(E21>G21,0.001,0),0) -> 0 | MC5: =SUM(LY5:MB5) -> 6.15 | MD5: =RANK(MC5,$MC$3:$MC$6,0) -> 2 | ME5: =IF(OR(AND(MD3=MD4,MD3=MD5,MD3=MD6),AND(MD5=MD3,MD5=MD4)),MD5+2,IF(OR(AND(MD5=MD4,MD5=MD6),MD5=MD3,MD5=MD4),MD5+1,MD5)) -> 2 | MF5: 3 | MG5: =MATCH(MF5,$ME$3:$ME$6,0) -> 2 | MH5: =INDEX($LM$3:$LM$6,MG5) -> Equador
LM6: Holanda | LN6: =IF(OR(G21="",E21=""),0,IF(LO6=0,0,IF(G21>E21,3,IF(G21=E21,1,0)))+IF(OR(E23="",G23=""),0,IF(E23>G23,3,IF(E23=G23,1,0)))+IF(OR(E25="",G25=""),0,IF(E25>G25,3,IF(E25=G25,1,0)))) -> 7 | LO6: =IF(AND(E21<>"",G21<>""),1,0)+IF(AND(E23<>"",G23<>""),1,0)+IF(AND(E25<>"",G25<>""),1,0) -> 3 | LP6: =IF(OR(G21="",E21=""),0,IF(G21>E21,1,0))+IF(OR(E23="",G23=""),0,IF(E23>G23,1,0))+IF(OR(E25="",G25=""),0,IF(E25>G25,1,0)) -> 2 | LQ6: =IF(OR(G21="",E21=""),0,IF(G21=E21,1,0))+IF(OR(E23="",G23=""),0,IF(E23=G23,1,0))+IF(OR(E25="",G25=""),0,IF(E25=G25,1,0)) -> 1 | LR6: =IF(OR(G21="",E21=""),0,IF(G21<E21,1,0))+IF(OR(E23="",G23=""),0,IF(E23<G23,1,0))+IF(OR(E25="",G25=""),0,IF(E25<G25,1,0)) -> 0 | LS6: =G21+E23+E25 -> 5 | LT6: =E21+G23+G25 -> 1 | LU6: =LS6-LT6 -> 4 | LV6: =LN6 -> 7 | LW6: =LU6/10 -> 0.4 | LX6: =LS6/100 -> 0.05 | LY6: =SUM(LV6:LX6) -> 7.45 | LZ6: =IF(LY6=LY3,IF(E25>G25,0.001,0),0) -> 0 | MA6: =IF(LY6=LY4,IF(E23>G23,0.001,0),0) -> 0 | MB6: =IF(LY6=LY5,IF(G21>E21,0.001,0),0) -> 0 | MC6: =SUM(LY6:MB6) -> 7.45 | MD6: =RANK(MC6,$MC$3:$MC$6,0) -> 1 | ME6: =IF(AND(MD3=MD4,MD3=MD5,MD3=MD6),MD6+3,IF(OR(AND(MD6=MD5,MD6=MD4),AND(MD6=MD4,MD6=MD3)),MD6+2,IF(OR(MD6=MD5,MD6=MD4,MD6=MD3),MD6+1,MD6))) -> 1 | MF6: 4 | MG6: =MATCH(MF6,$ME$3:$ME$6,0) -> 1 | MH6: =INDEX($LM$3:$LM$6,MG6) -> Catar
LN9: Grupo B
LM10: Seleção | LN10: PT | LO10: J | LP10: V | LQ10: E | LR10: D | LS10: GP | LT10: GC | LU10: SG
LM11: Inglaterra | LN11: =IF(OR(E28="",G28=""),0,IF(LO11=0,0,IF(E28>G28,3,IF(E28=G28,1,0)))+IF(OR(E31="",G31=""),0,IF(E31>G31,3,IF(E31=G31,1,0)))+IF(OR(G32="",E32=""),0,IF(G32>E32,3,IF(G32=E32,1,0)))) -> 7 | LO11: =IF(AND(E28<>"",G28<>""),1,0)+IF(AND(E31<>"",G31<>""),1,0)+IF(AND(E32<>"",G32<>""),1,0) -> 3 | LP11: =IF(OR(E28="",G28=""),0,IF(E28>G28,1,0))+IF(OR(E31="",G31=""),0,IF(E31>G31,1,0))+IF(OR(G32="",E32=""),0,IF(G32>E32,1,0)) -> 2 | LQ11: =IF(OR(E28="",G28=""),0,IF(E28=G28,1,0))+IF(OR(E31="",G31=""),0,IF(E31=G31,1,0))+IF(OR(G32="",E32=""),0,IF(G32=E32,1,0)) -> 1 | LR11: =IF(OR(E28="",G28=""),0,IF(E28<G28,1,0))+IF(OR(E31="",G31=""),0,IF(E31<G31,1,0))+IF(OR(G32="",E32=""),0,IF(G32<E32,1,0)) -> 0 | LS11: =E28+E31+G32 -> 9 | LT11: =G28+G31+E32 -> 2 | LU11: =LS11-LT11 -> 7 | LV11: =LN11 -> 7 | LW11: =LU11/10 -> 0.7 | LX11: =LS11/100 -> 0.09 | LY11: =SUM(LV11:LX11) -> 7.79 | LZ11: =IF(LY11=LY12,IF(E28>G28,0.001,0),0) -> 0 | MA11: =IF(LY11=LY13,IF(E31>G31,0.001,0),0) -> 0 | MB11: =IF(LY11=LY14,IF(G32>E32,0.001,0),0) -> 0 | MC11: =SUM(LY11:MB11) -> 7.79 | MD11: =RANK($MC$11,$MC$11:$MC$14,0) -> 1 | ME11: =MD11 -> 1 | MF11: 1 | MG11: =MATCH(MF11,$ME$11:$ME$14,0) -> 1 | MH11: =INDEX($LM$11:$LM$14,MG11) -> Inglaterra
LM12: Irã | LN12: =IF(OR(G28="",E28=""),0,IF(LO12=0,0,IF(G28>E28,3,IF(G28=E28,1,0)))+IF(OR(G30="",E30=""),0,IF(G30>E30,3,IF(G30=E30,1,0)))+IF(OR(G33="",E33=""),0,IF(E33>G33,3,IF(E33=G33,1,0)))) -> 3 | LO12: =IF(AND(E28<>"",G28<>""),1,0)+IF(AND(E30<>"",G30<>""),1,0)+IF(AND(E33<>"",G33<>""),1,0) -> 3 | LP12: =IF(OR(G28="",E28=""),0,IF(G28>E28,1,0))+IF(OR(G30="",E30=""),0,IF(G30>E30,1,0))+IF(OR(E33="",G33=""),0,IF(E33>G33,1,0)) -> 1 | LQ12: =IF(OR(G28="",E28=""),0,IF(G28=E28,1,0))+IF(OR(G30="",E30=""),0,IF(G30=E30,1,0))+IF(OR(E33="",G33=""),0,IF(E33=G33,1,0)) -> 0 | LR12: =IF(OR(G28="",E28=""),0,IF(G28<E28,1,0))+IF(OR(G30="",E30=""),0,IF(G30<E30,1,0))+IF(OR(E33="",G33=""),0,IF(E33<G33,1,0)) -> 2 | LS12: =G28+G30+E33 -> 4 | LT12: =E28+E30+G33 -> 7 | LU12: =LS12-LT12 -> -3 | LV12: =LN12 -> 3 | LW12: =LU12/10 -> -0.3 | LX12: =LS12/100 -> 0.04 | LY12: =SUM(LV12:LX12) -> 2.74 | LZ12: =IF(LY12=LY11,IF(G28>E28,0.001,0),0) -> 0 | MA12: =IF(LY12=LY13,IF(E33>G33,0.001,0),0) -> 0 | MB12: =IF(LY12=LY14,IF(G30>E30,0.001,0),0) -> 0 | MC12: =SUM(LY12:MB12) -> 2.74 | MD12: =RANK($MC$12,$MC$11:$MC$14,0) -> 3 | ME12: =IF(OR(AND(MD11=MD12,MD11=MD13,MD11=MD14),AND(MD12=MD11,MD12=MD13),AND(MD12=MD11,MD12=MD14),MD12=MD11),MD12+1,MD12) -> 3 | MF12: 2 | MG12: =MATCH(MF12,$ME$11:$ME$14,0) -> 3 | MH12: =INDEX($LM$11:$LM$14,MG12) -> Estados Unidos
LM13: Estados Unidos | LN13: =IF(OR(E29="",G29=""),0,IF(LO13=0,0,IF(E29>G29,3,IF(E29=G29,1,0)))+IF(OR(G31="",E31=""),0,IF(G31>E31,3,IF(G31=E31,1,0)))+IF(OR(G33="",E33=""),0,IF(G33>E33,3,IF(E33=G33,1,0)))) -> 5 | LO13: =IF(AND(E29<>"",G29<>""),1,0)+IF(AND(E31<>"",G31<>""),1,0)+IF(AND(E33<>"",G33<>""),1,0) -> 3 | LP13: =IF(OR(E29="",G29=""),0,IF(E29>G29,1,0))+IF(OR(G31="",E31=""),0,IF(G31>E31,1,0))+IF(OR(G33="",E33=""),0,IF(G33>E33,1,0)) -> 1 | LQ13: =IF(OR(E29="",G29=""),0,IF(E29=G29,1,0))+IF(OR(G31="",E31=""),0,IF(G31=E31,1,0))+IF(OR(G33="",E33=""),0,IF(G33=E33,1,0)) -> 2 | LR13: =IF(OR(E29="",G29=""),0,IF(E29<G29,1,0))+IF(OR(G31="",E31=""),0,IF(G31<E31,1,0))+IF(OR(G33="",E33=""),0,IF(G33<E33,1,0)) -> 0 | LS13: =E29+G31+G33 -> 2 | LT13: =G29+E31+E33 -> 1 | LU13: =LS13-LT13 -> 1 | LV13: =LN13 -> 5 | LW13: =LU13/10 -> 0.1 | LX13: =LS13/100 -> 0.02 | LY13: =SUM(LV13:LX13) -> 5.12 | LZ13: =IF(LY13=LY11,IF(G31>E31,0.001,0),0) -> 0 | MA13: =IF(LY13=LY12,IF(G33>E33,0.001,0),0) -> 0 | MB13: =IF(LY13=LY14,IF(E29>G29,0.001,0),0) -> 0 | MC13: =SUM(LY13:MB13) -> 5.12 | MD13: =RANK($MC$13,$MC$11:$MC$14,0) -> 2 | ME13: =IF(OR(AND(MD11=MD12,MD11=MD13,MD11=MD14),AND(MD13=MD11,MD13=MD12)),MD13+2,IF(OR(AND(MD13=MD12,MD13=MD14),MD13=MD11,MD13=MD12),MD13+1,MD13)) -> 2 | MF13: 3 | MG13: =MATCH(MF13,$ME$11:$ME$14,0) -> 2 | MH13: =INDEX($LM$11:$LM$14,MG13) -> Irã
LM14: País de Gales | LN14: =IF(OR(G29="",E29=""),0,IF(LO14=0,0,IF(G29>E29,3,IF(G29=E29,1,0)))+IF(OR(E30="",G30=""),0,IF(E30>G30,3,IF(E30=G30,1,0)))+IF(OR(E32="",G32=""),0,IF(E32>G32,3,IF(E32=G32,1,0)))) -> 1 | LO14: =IF(AND(E29<>"",G29<>""),1,0)+IF(AND(E30<>"",G30<>""),1,0)+IF(AND(E32<>"",G32<>""),1,0) -> 3 | LP14: =IF(OR(G29="",E29=""),0,IF(G29>E29,1,0))+IF(OR(E30="",G30=""),0,IF(E30>G30,1,0))+IF(OR(E32="",G32=""),0,IF(E32>G32,1,0)) -> 0 | LQ14: =IF(OR(G29="",E29=""),0,IF(G29=E29,1,0))+IF(OR(E30="",G30=""),0,IF(E30=G30,1,0))+IF(OR(E32="",G32=""),0,IF(E32=G32,1,0)) -> 1 | LR14: =IF(OR(G29="",E29=""),0,IF(G29<E29,1,0))+IF(OR(E30="",G30=""),0,IF(E30<G30,1,0))+IF(OR(E32="",G32=""),0,IF(E32<G32,1,0)) -> 2 | LS14: =G29+E30+E32 -> 1 | LT14: =E29+G30+G32 -> 6 | LU14: =LS14-LT14 -> -5 | LV14: =LN14 -> 1 | LW14: =LU14/10 -> -0.5 | LX14: =LS14/100 -> 0.01 | LY14: =SUM(LV14:LX14) -> 0.51 | LZ14: =IF(LY14=LY11,IF(E32>G32,0.001,0),0) -> 0 | MA14: =IF(LY14=LY12,IF(E30>G30,0.001,0),0) -> 0 | MB14: =IF(LY14=LY13,IF(G29>E29,0.001,0),0) -> 0 | MC14: =SUM(LY14:MB14) -> 0.51 | MD14: =RANK($MC$14,$MC$11:$MC$14,0) -> 4 | ME14: =IF(AND(MD11=MD12,MD11=MD13,MD11=MD14),MD14+3,IF(OR(AND(MD14=MD13,MD14=MD12),AND(MD14=MD12,MD14=MD11)),MD14+2,IF(OR(MD14=MD13,MD14=MD12,MD14=MD11),MD14+1,MD14))) -> 4 | MF14: 4 | MG14: =MATCH(MF14,$ME$11:$ME$14,0) -> 4 | MH14: =INDEX($LM$11:$LM$14,MG14) -> País de Gales
A17: 1a Fase | LN17: Grupo C
LM18: Seleção | LN18: PT | LO18: J | LP18: V | LQ18: E | LR18: D | LS18: GP | LT18: GC | LU18: SG
A19: Primeira fase GRUPO A | LM19: Argentina | LN19: =IF(OR(E36="",G36=""),0,IF(LO19=0,0,IF(E36>G36,3,IF(E36=G36,1,0)))+IF(OR(E39="",G39=""),0,IF(E39>G39,3,IF(E39=G39,1,0)))+IF(OR(G40="",E40=""),0,IF(G40>E40,3,IF(G40=E40,1,0)))) -> 6 | LO19: =IF(AND(E36<>"",G36<>""),1,0)+IF(AND(E39<>"",G39<>""),1,0)+IF(AND(E40<>"",G40<>""),1,0) -> 3 | LP19: =IF(OR(E36="",G36=""),0,IF(E36>G36,1,0))+IF(OR(E39="",G39=""),0,IF(E39>G39,1,0))+IF(OR(G40="",E40=""),0,IF(G40>E40,1,0)) -> 2 | LQ19: =IF(OR(E36="",G36=""),0,IF(E36=G36,1,0))+IF(OR(E39="",G39=""),0,IF(E39=G39,1,0))+IF(OR(G40="",E40=""),0,IF(G40=E40,1,0)) -> 0 | LR19: =IF(OR(E36="",G36=""),0,IF(E36<G36,1,0))+IF(OR(E39="",G39=""),0,IF(E39<G39,1,0))+IF(OR(G40="",E40=""),0,IF(G40<E40,1,0)) -> 1 | LS19: =E36+E39+G40 -> 5 | LT19: =G36+G39+E40 -> 2 | LU19: =LS19-LT19 -> 3 | LV19: =LN19 -> 6 | LW19: =LU19/10 -> 0.3 | LX19: =LS19/100 -> 0.05 | LY19: =SUM(LV19:LX19) -> 6.35 | LZ19: =IF(LY19=LY20,IF(E36>G36,0.001,0),0) -> 0 | MA19: =IF(LY19=LY21,IF(E39>G39,0.001,0),0) -> 0 | MB19: =IF(LY19=LY22,IF(G40>E40,0.001,0),0) -> 0 | MC19: =SUM(LY19:MB19) -> 6.35 | MD19: =RANK($MC$19,$MC$19:$MC$22,0) -> 1 | ME19: =MD19 -> 1 | MF19: 1 | MG19: =MATCH(MF19,$ME$19:$ME$22,0) -> 1 | MH19: =INDEX($LM$19:$LM$22,MG19) -> Argentina
A20: 44885 | B20: 0.54166667 | C20: Catar | E20: 0 | F20: x | G20: 2 | I20: Equador | J20: Al Bayt | L20: Classificação do grupo A | LM20: Arábia Saudita | LN20: =IF(OR(G36="",E36=""),0,IF(LO20=0,0,IF(G36>E36,3,IF(G36=E36,1,0)))+IF(OR(G38="",E38=""),0,IF(G38>E38,3,IF(G38=E38,1,0)))+IF(OR(G41="",E41=""),0,IF(E41>G41,3,IF(E41=G41,1,0)))) -> 3 | LO20: =IF(AND(E36<>"",G36<>""),1,0)+IF(AND(E38<>"",G38<>""),1,0)+IF(AND(E41<>"",G41<>""),1,0) -> 3 | LP20: =IF(OR(G36="",E36=""),0,IF(G36>E36,1,0))+IF(OR(G38="",E38=""),0,IF(G38>E38,1,0))+IF(OR(E41="",G41=""),0,IF(E41>G41,1,0)) -> 1 | LQ20: =IF(OR(G36="",E36=""),0,IF(G36=E36,1,0))+IF(OR(G38="",E38=""),0,IF(G38=E38,1,0))+IF(OR(E41="",G41=""),0,IF(E41=G41,1,0)) -> 0 | LR20: =IF(OR(G36="",E36=""),0,IF(G36<E36,1,0))+IF(OR(G38="",E38=""),0,IF(G38<E38,1,0))+IF(OR(E41="",G41=""),0,IF(E41<G41,1,0)) -> 2 | LS20: =G36+G38+E41 -> 3 | LT20: =E36+E38+G41 -> 5 | LU20: =LS20-LT20 -> -2 | LV20: =LN20 -> 3 | LW20: =LU20/10 -> -0.2 | LX20: =LS20/100 -> 0.03 | LY20: =SUM(LV20:LX20) -> 2.83 | LZ20: =IF(LY20=LY19,IF(G36>E36,0.001,0),0) -> 0 | MA20: =IF(LY20=LY21,IF(E41>G41,0.001,0),0) -> 0 | MB20: =IF(LY20=LY22,IF(G38>E38,0.001,0),0) -> 0 | MC20: =SUM(LY20:MB20) -> 2.83 | MD20: =RANK($MC$20,$MC$19:$MC$22,0) -> 4 | ME20: =IF(OR(AND(MD19=MD20,MD19=MD21,MD19=MD22),AND(MD20=MD19,MD20=MD21),AND(MD20=MD19,MD20=MD22),MD20=MD19),MD20+1,MD20) -> 4 | MF20: 2 | MG20: =MATCH(MF20,$ME$19:$ME$22,0) -> 4 | MH20: =INDEX($LM$19:$LM$22,MG20) -> Polônia
A21: 44886 | B21: 0.54166667 | C21: Senegal | E21: 0 | F21: x | G21: 2 | I21: Holanda | J21: Al Thumana | M21: PT | N21: J | O21: V | P21: E | Q21: D | R21: GP | S21: GC | T21: SG | V21: =A19 -> Primeira fase GRUPO A | LM21: México | LN21: =IF(OR(E37="",G37=""),0,IF(LO21=0,0,IF(E37>G37,3,IF(E37=G37,1,0)))+IF(OR(G39="",E39=""),0,IF(G39>E39,3,IF(G39=E39,1,0)))+IF(OR(G41="",E41=""),0,IF(G41>E41,3,IF(E41=G41,1,0)))) -> 4 | LO21: =IF(AND(E37<>"",G37<>""),1,0)+IF(AND(E39<>"",G39<>""),1,0)+IF(AND(E41<>"",G41<>""),1,0) -> 3 | LP21: =IF(OR(E37="",G37=""),0,IF(E37>G37,1,0))+IF(OR(G39="",E39=""),0,IF(G39>E39,1,0))+IF(OR(G41="",E41=""),0,IF(G41>E41,1,0)) -> 1 | LQ21: =IF(OR(E37="",G37=""),0,IF(E37=G37,1,0))+IF(OR(G39="",E39=""),0,IF(G39=E39,1,0))+IF(OR(G41="",E41=""),0,IF(G41=E41,1,0)) -> 1 | LR21: =IF(OR(E37="",G37=""),0,IF(E37<G37,1,0))+IF(OR(G39="",E39=""),0,IF(G39<E39,1,0))+IF(OR(G41="",E41=""),0,IF(G41<E41,1,0)) -> 1 | LS21: =E37+G39+G41 -> 2 | LT21: =G37+E39+E41 -> 3 | LU21: =LS21-LT21 -> -1 | LV21: =LN21 -> 4 | LW21: =LU21/10 -> -0.1 | LX21: =LS21/100 -> 0.02 | LY21: =SUM(LV21:LX21) -> 3.92 | LZ21: =IF(LY21=LY19,IF(G39>E39,0.001,0),0) -> 0 | MA21: =IF(LY21=LY20,IF(G41>E41,0.001,0),0) -> 0 | MB21: =IF(LY21=LY22,IF(E37>G37,0.001,0),0) -> 0 | MC21: =SUM(LY21:MB21) -> 3.92 | MD21: =RANK($MC$21,$MC$19:$MC$22,0) -> 3 | ME21: =IF(OR(AND(MD19=MD20,MD19=MD21,MD19=MD22),AND(MD21=MD19,MD21=MD20)),MD21+2,IF(OR(AND(MD21=MD20,MD21=MD22),MD21=MD19,MD21=MD20),MD21+1,MD21)) -> 3 | MF21: 3 | MG21: =MATCH(MF21,$ME$19:$ME$22,0) -> 3 | MH21: =INDEX($LM$19:$LM$22,MG21) -> México
A22: 44890 | B22: 0.41666667 | C22: Catar | E22: 1 | F22: x | G22: 3 | I22: Senegal | J22: Al Thumana | L22: ='Resultado Oficial'!MH3 -> Holanda | M22: =VLOOKUP(L22,'Resultado Oficial'!$LM$3:$LU$6,2,FALSE) -> 7 | N22: =VLOOKUP(L22,'Resultado Oficial'!$LM$3:$LU$6,3,FALSE) -> 3 | O22: =VLOOKUP(L22,'Resultado Oficial'!$LM$3:$LU$6,4,FALSE) -> 2 | P22: =VLOOKUP(L22,'Resultado Oficial'!$LM$3:$LU$6,5,FALSE) -> 1 | Q22: =VLOOKUP(L22,'Resultado Oficial'!$LM$3:$LU$6,6,FALSE) -> 0 | R22: =VLOOKUP(L22,'Resultado Oficial'!$LM$3:$LU$6,7,FALSE) -> 5 | S22: =VLOOKUP(L22,'Resultado Oficial'!$LM$3:$LU$6,8,FALSE) -> 1 | T22: =VLOOKUP(L22,'Resultado Oficial'!$LM$3:$LU$6,9,FALSE) -> 4 | V22: 1o Colocado | W22: =IF(SUM(N22:N25)<>12,"",L22) -> Holanda | LM22: Polônia | LN22: =IF(OR(G37="",E37=""),0,IF(LO22=0,0,IF(G37>E37,3,IF(G37=E37,1,0)))+IF(OR(E38="",G38=""),0,IF(E38>G38,3,IF(E38=G38,1,0)))+IF(OR(E40="",G40=""),0,IF(E40>G40,3,IF(E40=G40,1,0)))) -> 4 | LO22: =IF(AND(E37<>"",G37<>""),1,0)+IF(AND(E38<>"",G38<>""),1,0)+IF(AND(E40<>"",G40<>""),1,0) -> 3 | LP22: =IF(OR(G37="",E37=""),0,IF(G37>E37,1,0))+IF(OR(E38="",G38=""),0,IF(E38>G38,1,0))+IF(OR(E40="",G40=""),0,IF(E40>G40,1,0)) -> 1 | LQ22: =IF(OR(G37="",E37=""),0,IF(G37=E37,1,0))+IF(OR(E38="",G38=""),0,IF(E38=G38,1,0))+IF(OR(E40="",G40=""),0,IF(E40=G40,1,0)) -> 1 | LR22: =IF(OR(G37="",E37=""),0,IF(G37<E37,1,0))+IF(OR(E38="",G38=""),0,IF(E38<G38,1,0))+IF(OR(E40="",G40=""),0,IF(E40<G40,1,0)) -> 1 | LS22: =G37+E38+E40 -> 2 | LT22: =E37+G38+G40 -> 2 | LU22: =LS22-LT22 -> 0 | LV22: =LN22 -> 4 | LW22: =LU22/10 -> 0 | LX22: =LS22/100 -> 0.02 | LY22: =SUM(LV22:LX22) -> 4.02 | LZ22: =IF(LY22=LY19,IF(E40>G40,0.001,0),0) -> 0 | MA22: =IF(LY22=LY20,IF(E38>G38,0.001,0),0) -> 0 | MB22: =IF(LY22=LY21,IF(G37>E37,0.001,0),0) -> 0 | MC22: =SUM(LY22:MB22) -> 4.02 | MD22: =RANK($MC$22,$MC$19:$MC$22,0) -> 2 | ME22: =IF(AND(MD19=MD20,MD19=MD21,MD19=MD22),MD22+3,IF(OR(AND(MD22=MD21,MD22=MD20),AND(MD22=MD20,MD22=MD19)),MD22+2,IF(OR(MD22=MD21,MD22=MD20,MD22=MD19),MD22+1,MD22))) -> 2 | MF22: 4 | MG22: =MATCH(MF22,$ME$19:$ME$22,0) -> 2 | MH22: =INDEX($LM$19:$LM$22,MG22) -> Arábia Saudita
A23: 44890 | B23: 0.54166667 | C23: Holanda | E23: 1 | F23: x | G23: 1 | I23: Equador | J23: Intern. Khalifa | L23: ='Resultado Oficial'!MH4 -> Senegal | M23: =VLOOKUP(L23,'Resultado Oficial'!$LM$3:$LU$6,2,FALSE) -> 6 | N23: =VLOOKUP(L23,'Resultado Oficial'!$LM$3:$LU$6,3,FALSE) -> 3 | O23: =VLOOKUP(L23,'Resultado Oficial'!$LM$3:$LU$6,4,FALSE) -> 2 | P23: =VLOOKUP(L23,'Resultado Oficial'!$LM$3:$LU$6,5,FALSE) -> 0 | Q23: =VLOOKUP(L23,'Resultado Oficial'!$LM$3:$LU$6,6,FALSE) -> 1 | R23: =VLOOKUP(L23,'Resultado Oficial'!$LM$3:$LU$6,7,FALSE) -> 5 | S23: =VLOOKUP(L23,'Resultado Oficial'!$LM$3:$LU$6,8,FALSE) -> 4 | T23: =VLOOKUP(L23,'Resultado Oficial'!$LM$3:$LU$6,9,FALSE) -> 1 | V23: 2o Colocado | W23: =IF(SUM(N22:N25)<>12,"",L23) -> Senegal
A24: 44894 | B24: 0.5 | C24: Equador | E24: 1 | F24: x | G24: 2 | I24: Senegal | J24: Intern. Khalifa | L24: ='Resultado Oficial'!MH5 -> Equador | M24: =VLOOKUP(L24,'Resultado Oficial'!$LM$3:$LU$6,2,FALSE) -> 4 | N24: =VLOOKUP(L24,'Resultado Oficial'!$LM$3:$LU$6,3,FALSE) -> 3 | O24: =VLOOKUP(L24,'Resultado Oficial'!$LM$3:$LU$6,4,FALSE) -> 2 | P24: =VLOOKUP(L24,'Resultado Oficial'!$LM$3:$LU$6,5,FALSE) -> 1 | Q24: =VLOOKUP(L24,'Resultado Oficial'!$LM$3:$LU$6,6,FALSE) -> 0 | R24: =VLOOKUP(L24,'Resultado Oficial'!$LM$3:$LU$6,7,FALSE) -> 5 | S24: =VLOOKUP(L24,'Resultado Oficial'!$LM$3:$LU$6,8,FALSE) -> 1 | T24: =VLOOKUP(L24,'Resultado Oficial'!$LM$3:$LU$6,9,FALSE) -> 4
A25: 44894 | B25: 0.5 | C25: Holanda | E25: 2 | F25: x | G25: 0 | I25: Qatar | J25: Al Bayt | L25: ='Resultado Oficial'!MH6 -> Catar | M25: =VLOOKUP(L25,'Resultado Oficial'!$LM$3:$LU$6,2,FALSE) -> 0 | N25: =VLOOKUP(L25,'Resultado Oficial'!$LM$3:$LU$6,3,FALSE) -> 3 | O25: =VLOOKUP(L25,'Resultado Oficial'!$LM$3:$LU$6,4,FALSE) -> 0 | P25: =VLOOKUP(L25,'Resultado Oficial'!$LM$3:$LU$6,5,FALSE) -> 0 | Q25: =VLOOKUP(L25,'Resultado Oficial'!$LM$3:$LU$6,6,FALSE) -> 3 | R25: =VLOOKUP(L25,'Resultado Oficial'!$LM$3:$LU$6,7,FALSE) -> 1 | S25: =VLOOKUP(L25,'Resultado Oficial'!$LM$3:$LU$6,8,FALSE) -> 7 | T25: =VLOOKUP(L25,'Resultado Oficial'!$LM$3:$LU$6,9,FALSE) -> -6 | LN25: Grupo D
LM26: Seleção | LN26: PT | LO26: J | LP26: V | LQ26: E | LR26: D | LS26: GP | LT26: GC | LU26: SG
A27: Primeira fase GRUPO B | LM27: França | LN27: =IF(OR(E45="",G45=""),0,IF(LO27=0,0,IF(E45>G45,3,IF(E45=G45,1,0)))+IF(OR(E47="",G47=""),0,IF(E47>G47,3,IF(E47=G47,1,0)))+IF(OR(G49="",E49=""),0,IF(G49>E49,3,IF(G49=E49,1,0)))) -> 6 | LO27: =IF(AND(E45<>"",G45<>""),1,0)+IF(AND(E47<>"",G47<>""),1,0)+IF(AND(E49<>"",G49<>""),1,0) -> 3 | LP27: =IF(OR(E45="",G45=""),0,IF(E45>G45,1,0))+IF(OR(E47="",G47=""),0,IF(E47>G47,1,0))+IF(OR(G49="",E49=""),0,IF(G49>E49,1,0)) -> 2 | LQ27: =IF(OR(E45="",G45=""),0,IF(E45=G45,1,0))+IF(OR(E47="",G47=""),0,IF(E47=G47,1,0))+IF(OR(G49="",E49=""),0,IF(G49=E49,1,0)) -> 0 | LR27: =IF(OR(E45="",G45=""),0,IF(E45<G45,1,0))+IF(OR(E47="",G47=""),0,IF(E47<G47,1,0))+IF(OR(G49="",E49=""),0,IF(G49<E49,1,0)) -> 1 | LS27: =E45+E47+G49 -> 6 | LT27: =G45+G47+E49 -> 3 | LU27: =LS27-LT27 -> 3 | LV27: =LN27 -> 6 | LW27: =LU27/10 -> 0.3 | LX27: =LS27/100 -> 0.06 | LY27: =SUM(LV27:LX27) -> 6.36 | LZ27: =IF(LY27=LY28,IF(E45>G45,0.001,0),0) -> 0 | MA27: =IF(LY27=LY29,IF(E47>G47,0.001,0),0) -> 0 | MB27: =IF(LY27=LY30,IF(G49>E49,0.001,0),0) -> 0 | MC27: =SUM(LY27:MB27) -> 6.36 | MD27: =RANK($MC$27,$MC$27:$MC$30,0) -> 1 | ME27: =MD27 -> 1 | MF27: 1 | MG27: =MATCH(MF27,$ME$27:$ME$30,0) -> 1 | MH27: =INDEX($LM$27:$LM$30,MG27) -> França
A28: 44886 | B28: 0.41666667 | C28: Inglaterra | E28: 6 | F28: x | G28: 2 | I28: Irã | J28: Intern. Khalifa | L28: Classificação do grupo B | LM28: Austrália | LN28: =IF(OR(G45="",E45=""),0,IF(LO28=0,0,IF(G45>E45,3,IF(G45=E45,1,0)))+IF(OR(G46="",E46=""),0,IF(G46>E46,3,IF(G46=E46,1,0)))+IF(OR(G48="",E48=""),0,IF(E48>G48,3,IF(E48=G48,1,0)))) -> 6 | LO28: =IF(AND(E45<>"",G45<>""),1,0)+IF(AND(E46<>"",G46<>""),1,0)+IF(AND(E48<>"",G48<>""),1,0) -> 3 | LP28: =IF(OR(G45="",E45=""),0,IF(G45>E45,1,0))+IF(OR(G46="",E46=""),0,IF(G46>E46,1,0))+IF(OR(E48="",G48=""),0,IF(E48>G48,1,0)) -> 2 | LQ28: =IF(OR(G45="",E45=""),0,IF(G45=E45,1,0))+IF(OR(G46="",E46=""),0,IF(G46=E46,1,0))+IF(OR(E48="",G48=""),0,IF(E48=G48,1,0)) -> 0 | LR28: =IF(OR(G45="",E45=""),0,IF(G45<E45,1,0))+IF(OR(G46="",E46=""),0,IF(G46<E46,1,0))+IF(OR(E48="",G48=""),0,IF(E48<G48,1,0)) -> 1 | LS28: =G45+G46+E48 -> 3 | LT28: =E45+E46+G48 -> 4 | LU28: =LS28-LT28 -> -1 | LV28: =LN28 -> 6 | LW28: =LU28/10 -> -0.1 | LX28: =LS28/100 -> 0.03 | LY28: =SUM(LV28:LX28) -> 5.93 | LZ28: =IF(LY28=LY27,IF(G45>E45,0.001,0),0) -> 0 | MA28: =IF(LY28=LY29,IF(E48>G48,0.001,0),0) -> 0 | MB28: =IF(LY28=LY30,IF(G46>E46,0.001,0),0) -> 0 | MC28: =SUM(LY28:MB28) -> 5.93 | MD28: =RANK($MC$28,$MC$27:$MC$30,0) -> 2 | ME28: =IF(OR(AND(MD27=MD28,MD27=MD29,MD27=MD30),AND(MD28=MD27,MD28=MD29),AND(MD28=MD27,MD28=MD30),MD28=MD27),MD28+1,MD28) -> 2 | MF28: 2 | MG28: =MATCH(MF28,$ME$27:$ME$30,0) -> 2 | MH28: =INDEX($LM$27:$LM$30,MG28) -> Austrália
A29: 44886 | B29: 0.66666667 | C29: Estados Unidos | E29: 1 | F29: x | G29: 1 | I29: País de Gales | J29: Al Rayan | M29: PT | N29: J | O29: V | P29: E | Q29: D | R29: GP | S29: GC | T29: SG | V29: =A27 -> Primeira fase GRUPO B | LM29: Dinamarca | LN29: =IF(OR(E44="",G44=""),0,IF(LO29=0,0,IF(E44>G44,3,IF(E44=G44,1,0)))+IF(OR(G47="",E47=""),0,IF(G47>E47,3,IF(G47=E47,1,0)))+IF(OR(G48="",E48=""),0,IF(G48>E48,3,IF(E48=G48,1,0)))) -> 1 | LO29: =IF(AND(E44<>"",G44<>""),1,0)+IF(AND(E47<>"",G47<>""),1,0)+IF(AND(E48<>"",G48<>""),1,0) -> 3 | LP29: =IF(OR(E44="",G44=""),0,IF(E44>G44,1,0))+IF(OR(G47="",E47=""),0,IF(G47>E47,1,0))+IF(OR(G48="",E48=""),0,IF(G48>E48,1,0)) -> 0 | LQ29: =IF(OR(E44="",G44=""),0,IF(E44=G44,1,0))+IF(OR(G47="",E47=""),0,IF(G47=E47,1,0))+IF(OR(G48="",E48=""),0,IF(G48=E48,1,0)) -> 1 | LR29: =IF(OR(E44="",G44=""),0,IF(E44<G44,1,0))+IF(OR(G47="",E47=""),0,IF(G47<E47,1,0))+IF(OR(G48="",E48=""),0,IF(G48<E48,1,0)) -> 2 | LS29: =E44+G47+G48 -> 1 | LT29: =G44+E47+E48 -> 3 | LU29: =LS29-LT29 -> -2 | LV29: =LN29 -> 1 | LW29: =LU29/10 -> -0.2 | LX29: =LS29/100 -> 0.01 | LY29: =SUM(LV29:LX29) -> 0.81 | LZ29: =IF(LY29=LY27,IF(G47>E47,0.001,0),0) -> 0 | MA29: =IF(LY29=LY28,IF(G48>E48,0.001,0),0) -> 0 | MB29: =IF(LY29=LY30,IF(E44>G44,0.001,0),0) -> 0 | MC29: =SUM(LY29:MB29) -> 0.81 | MD29: =RANK($MC$29,$MC$27:$MC$30,0) -> 4 | ME29: =IF(OR(AND(MD27=MD28,MD27=MD29,MD27=MD30),AND(MD29=MD27,MD29=MD28)),MD29+2,IF(OR(AND(MD29=MD28,MD29=MD30),MD29=MD27,MD29=MD28),MD29+1,MD29)) -> 4 | MF29: 3 | MG29: =MATCH(MF29,$ME$27:$ME$30,0) -> 4 | MH29: =INDEX($LM$27:$LM$30,MG29) -> Tunísia
A30: 44890 | B30: 0.29166667 | C30: País de Gales | E30: 0 | F30: x | G30: 2 | I30: Irã | J30: Al Rayan | L30: ='Resultado Oficial'!MH11 -> Inglaterra | M30: =VLOOKUP(L30,'Resultado Oficial'!$LM$11:$LU$14,2,FALSE) -> 7 | N30: =VLOOKUP(L30,'Resultado Oficial'!$LM$11:$LU$14,3,FALSE) -> 3 | O30: =VLOOKUP(L30,'Resultado Oficial'!$LM$11:$LU$14,4,FALSE) -> 2 | P30: =VLOOKUP(L30,'Resultado Oficial'!$LM$11:$LU$14,5,FALSE) -> 1 | Q30: =VLOOKUP(L30,'Resultado Oficial'!$LM$11:$LU$14,6,FALSE) -> 0 | R30: =VLOOKUP(L30,'Resultado Oficial'!$LM$11:$LU$14,7,FALSE) -> 9 | S30: =VLOOKUP(L30,'Resultado Oficial'!$LM$11:$LU$14,8,FALSE) -> 2 | T30: =VLOOKUP(L30,'Resultado Oficial'!$LM$11:$LU$14,9,FALSE) -> 7 | V30: 1o Colocado | W30: =IF(SUM(N30:N33)<>12,"",L30) -> Inglaterra | LM30: Tunísia | LN30: =IF(OR(G44="",E44=""),0,IF(LO30=0,0,IF(G44>E44,3,IF(G44=E44,1,0)))+IF(OR(E46="",G46=""),0,IF(E46>G46,3,IF(E46=G46,1,0)))+IF(OR(E49="",G49=""),0,IF(E49>G49,3,IF(E49=G49,1,0)))) -> 4 | LO30: =IF(AND(E44<>"",G44<>""),1,0)+IF(AND(E46<>"",G46<>""),1,0)+IF(AND(E49<>"",G49<>""),1,0) -> 3 | LP30: =IF(OR(G44="",E44=""),0,IF(G44>E44,1,0))+IF(OR(E46="",G46=""),0,IF(E46>G46,1,0))+IF(OR(E49="",G49=""),0,IF(E49>G49,1,0)) -> 1 | LQ30: =IF(OR(G44="",E44=""),0,IF(G44=E44,1,0))+IF(OR(E46="",G46=""),0,IF(E46=G46,1,0))+IF(OR(E49="",G49=""),0,IF(E49=G49,1,0)) -> 1 | LR30: =IF(OR(G44="",E44=""),0,IF(G44<E44,1,0))+IF(OR(E46="",G46=""),0,IF(E46<G46,1,0))+IF(OR(E49="",G49=""),0,IF(E49<G49,1,0)) -> 1 | LS30: =G44+E46+E49 -> 1 | LT30: =E44+G46+G49 -> 1 | LU30: =LS30-LT30 -> 0 | LV30: =LN30 -> 4 | LW30: =LU30/10 -> 0 | LX30: =LS30/100 -> 0.01 | LY30: =SUM(LV30:LX30) -> 4.01 | LZ30: =IF(LY30=LY27,IF(E49>G49,0.001,0),0) -> 0 | MA30: =IF(LY30=LY28,IF(E46>G46,0.001,0),0) -> 0 | MB30: =IF(LY30=LY29,IF(G44>E44,0.001,0),0) -> 0 | MC30: =SUM(LY30:MB30) -> 4.01 | MD30: =RANK($MC$30,$MC$27:$MC$30,0) -> 3 | ME30: =IF(AND(MD27=MD28,MD27=MD29,MD27=MD30),MD30+3,IF(OR(AND(MD30=MD29,MD30=MD28),AND(MD30=MD28,MD30=MD27)),MD30+2,IF(OR(MD30=MD29,MD30=MD28,MD30=MD27),MD30+1,MD30))) -> 3 | MF30: 4 | MG30: =MATCH(MF30,$ME$27:$ME$30,0) -> 3 | MH30: =INDEX($LM$27:$LM$30,MG30) -> Dinamarca
A31: 44890 | B31: 0.66666667 | C31: Inglaterra | E31: 0 | F31: x | G31: 0 | I31: Estados Unidos | J31: Al Bayt | L31: ='Resultado Oficial'!MH12 -> Estados Unidos | M31: =VLOOKUP(L31,'Resultado Oficial'!$LM$11:$LU$14,2,FALSE) -> 5 | N31: =VLOOKUP(L31,'Resultado Oficial'!$LM$11:$LU$14,3,FALSE) -> 3 | O31: =VLOOKUP(L31,'Resultado Oficial'!$LM$11:$LU$14,4,FALSE) -> 1 | P31: =VLOOKUP(L31,'Resultado Oficial'!$LM$11:$LU$14,5,FALSE) -> 2 | Q31: =VLOOKUP(L31,'Resultado Oficial'!$LM$11:$LU$14,6,FALSE) -> 0 | R31: =VLOOKUP(L31,'Resultado Oficial'!$LM$11:$LU$14,7,FALSE) -> 2 | S31: =VLOOKUP(L31,'Resultado Oficial'!$LM$11:$LU$14,8,FALSE) -> 1 | T31: =VLOOKUP(L31,'Resultado Oficial'!$LM$11:$LU$14,9,FALSE) -> 1 | V31: 2o Colocado | W31: =IF(SUM(N30:N33)<>12,"",L31) -> Estados Unidos
A32: 44894 | B32: 0.66666667 | C32: País de Gales | E32: 0 | F32: x | G32: 3 | I32: Inglaterra | J32: Al Rayan | L32: ='Resultado Oficial'!MH13 -> Irã | M32: =VLOOKUP(L32,'Resultado Oficial'!$LM$11:$LU$14,2,FALSE) -> 3 | N32: =VLOOKUP(L32,'Resultado Oficial'!$LM$11:$LU$14,3,FALSE) -> 3 | O32: =VLOOKUP(L32,'Resultado Oficial'!$LM$11:$LU$14,4,FALSE) -> 1 | P32: =VLOOKUP(L32,'Resultado Oficial'!$LM$11:$LU$14,5,FALSE) -> 0 | Q32: =VLOOKUP(L32,'Resultado Oficial'!$LM$11:$LU$14,6,FALSE) -> 2 | R32: =VLOOKUP(L32,'Resultado Oficial'!$LM$11:$LU$14,7,FALSE) -> 4 | S32: =VLOOKUP(L32,'Resultado Oficial'!$LM$11:$LU$14,8,FALSE) -> 7 | T32: =VLOOKUP(L32,'Resultado Oficial'!$LM$11:$LU$14,9,FALSE) -> -3
A33: 44894 | B33: 0.66666667 | C33: Irã | E33: 0 | F33: x | G33: 1 | I33: Estados Unidos | J33: Al Thumana | L33: ='Resultado Oficial'!MH14 -> País de Gales | M33: =VLOOKUP(L33,'Resultado Oficial'!$LM$11:$LU$14,2,FALSE) -> 1 | N33: =VLOOKUP(L33,'Resultado Oficial'!$LM$11:$LU$14,3,FALSE) -> 3 | O33: =VLOOKUP(L33,'Resultado Oficial'!$LM$11:$LU$14,4,FALSE) -> 0 | P33: =VLOOKUP(L33,'Resultado Oficial'!$LM$11:$LU$14,5,FALSE) -> 1 | Q33: =VLOOKUP(L33,'Resultado Oficial'!$LM$11:$LU$14,6,FALSE) -> 2 | R33: =VLOOKUP(L33,'Resultado Oficial'!$LM$11:$LU$14,7,FALSE) -> 1 | S33: =VLOOKUP(L33,'Resultado Oficial'!$LM$11:$LU$14,8,FALSE) -> 6 | T33: =VLOOKUP(L33,'Resultado Oficial'!$LM$11:$LU$14,9,FALSE) -> -5 | LN33: Grupo E
LM34: Seleção | LN34: PT | LO34: J | LP34: V | LQ34: =IF(OR(E51="",G51=""),0,IF(E51=G51,1,0))+IF(OR(E53="",G53=""),0,IF(E53=G53,1,0))+IF(OR(G55="",E55=""),0,IF(G55=E55,1,0)) -> 1 | LR34: D | LS34: GP | LT34: GC | LU34: SG
A35: Primeira fase GRUPO C | LM35: Espanha | LN35: =IF(OR(E53="",G53=""),0,IF(LO35=0,0,IF(E53>G53,3,IF(E53=G53,1,0)))+IF(OR(E55="",G55=""),0,IF(E55>G55,3,IF(E55=G55,1,0)))+IF(OR(G56="",E56=""),0,IF(G56>E56,3,IF(G56=E56,1,0)))) -> 4 | LO35: =IF(AND(E53<>"",G53<>""),1,0)+IF(AND(E55<>"",G55<>""),1,0)+IF(AND(E56<>"",G56<>""),1,0) -> 3 | LP35: =IF(OR(E53="",G53=""),0,IF(E53>G53,1,0))+IF(OR(E55="",G55=""),0,IF(E55>G55,1,0))+IF(OR(G56="",E56=""),0,IF(G56>E56,1,0)) -> 1 | LQ35: =IF(OR(E53="",G53=""),0,IF(E53=G53,1,0))+IF(OR(E55="",G55=""),0,IF(E55=G55,1,0))+IF(OR(G56="",E56=""),0,IF(G56=E56,1,0)) -> 1 | LR35: =IF(OR(E53="",G53=""),0,IF(E53<G53,1,0))+IF(OR(E55="",G55=""),0,IF(E55<G55,1,0))+IF(OR(G56="",E56=""),0,IF(G56<E56,1,0)) -> 1 | LS35: =E53+E55+G56 -> 9 | LT35: =G53+G55+E56 -> 3 | LU35: =LS35-LT35 -> 6 | LV35: =LN35 -> 4 | LW35: =LU35/10 -> 0.6 | LX35: =LS35/100 -> 0.09 | LY35: =SUM(LV35:LX35) -> 4.69 | LZ35: =IF(LY35=LY36,IF(E53>G53,0.001,0),0) -> 0 | MA35: =IF(LY35=LY37,IF(E55>G55,0.001,0),0) -> 0 | MB35: =IF(LY35=LY38,IF(G56>E56,0.001,0),0) -> 0 | MC35: =SUM(LY35:MB35) -> 4.69 | MD35: =RANK($MC$35,$MC$35:$MC$38,0) -> 2 | ME35: =MD35 -> 2 | MF35: 1 | MG35: =MATCH(MF35,$ME$35:$ME$38,0) -> 4 | MH35: =INDEX($LM$35:$LM$38,MG35) -> Japão
A36: 44887 | B36: 0.29166667 | C36: Argentina | E36: 1 | F36: x | G36: 2 | I36: Arábia Saudita | J36: Lusail | L36: Classificação do grupo C | LM36: Costa Rica | LN36: =IF(OR(G53="",E53=""),0,IF(LO36=0,0,IF(G53>E53,3,IF(G53=E53,1,0)))+IF(OR(G54="",E54=""),0,IF(G54>E54,3,IF(G54=E54,1,0)))+IF(OR(G57="",E57=""),0,IF(E57>G57,3,IF(E57=G57,1,0)))) -> 3 | LO36: =IF(AND(E53<>"",G53<>""),1,0)+IF(AND(E54<>"",G54<>""),1,0)+IF(AND(E57<>"",G57<>""),1,0) -> 3 | LP36: =IF(OR(G53="",E53=""),0,IF(G53>E53,1,0))+IF(OR(G54="",E54=""),0,IF(G54>E54,1,0))+IF(OR(E57="",G57=""),0,IF(E57>G57,1,0)) -> 1 | LQ36: =IF(OR(G53="",E53=""),0,IF(G53=E53,1,0))+IF(OR(G54="",E54=""),0,IF(G54=E54,1,0))+IF(OR(E57="",G57=""),0,IF(E57=G57,1,0)) -> 0 | LR36: =IF(OR(G53="",E53=""),0,IF(G53<E53,1,0))+IF(OR(G54="",E54=""),0,IF(G54<E54,1,0))+IF(OR(E57="",G57=""),0,IF(E57<G57,1,0)) -> 2 | LS36: =G53+G54+E57 -> 3 | LT36: =E53+E54+G57 -> 11 | LU36: =LS36-LT36 -> -8 | LV36: =LN36 -> 3 | LW36: =LU36/10 -> -0.8 | LX36: =LS36/100 -> 0.03 | LY36: =SUM(LV36:LX36) -> 2.23 | LZ36: =IF(LY36=LY35,IF(G53>E53,0.001,0),0) -> 0 | MA36: =IF(LY36=LY37,IF(E57>G57,0.001,0),0) -> 0 | MB36: =IF(LY36=LY38,IF(G54>E54,0.001,0),0) -> 0 | MC36: =SUM(LY36:MB36) -> 2.23 | MD36: =RANK($MC$36,$MC$35:$MC$38,0) -> 4 | ME36: =IF(OR(AND(MD35=MD36,MD35=MD37,MD35=MD38),AND(MD36=MD35,MD36=MD37),AND(MD36=MD35,MD36=MD38),MD36=MD35),MD36+1,MD36) -> 4 | MF36: 2 | MG36: =MATCH(MF36,$ME$35:$ME$38,0) -> 1 | MH36: =INDEX($LM$35:$LM$38,MG36) -> Espanha
A37: 44887 | B37: 0.54166667 | C37: México | E37: 0 | F37: x | G37: 0 | I37: Polônia | J37: Estádio 974 | M37: PT | N37: J | O37: V | P37: E | Q37: D | R37: GP | S37: GC | T37: SG | V37: =A35 -> Primeira fase GRUPO C | LM37: Alemanha | LN37: =IF(OR(E52="",G52=""),0,IF(LO37=0,0,IF(E52>G52,3,IF(E52=G52,1,0)))+IF(OR(G55="",E55=""),0,IF(G55>E55,3,IF(G55=E55,1,0)))+IF(OR(G57="",E57=""),0,IF(G57>E57,3,IF(E57=G57,1,0)))) -> 4 | LO37: =IF(AND(E52<>"",G52<>""),1,0)+IF(AND(E55<>"",G55<>""),1,0)+IF(AND(E57<>"",G57<>""),1,0) -> 3 | LP37: =IF(OR(E52="",G52=""),0,IF(E52>G52,1,0))+IF(OR(G55="",E55=""),0,IF(G55>E55,1,0))+IF(OR(G57="",E57=""),0,IF(G57>E57,1,0)) -> 1 | LQ37: =IF(OR(E52="",G52=""),0,IF(E52=G52,1,0))+IF(OR(G55="",E55=""),0,IF(G55=E55,1,0))+IF(OR(G57="",E57=""),0,IF(G57=E57,1,0)) -> 1 | LR37: =IF(OR(E52="",G52=""),0,IF(E52<G52,1,0))+IF(OR(G55="",E55=""),0,IF(G55<E55,1,0))+IF(OR(G57="",E57=""),0,IF(G57<E57,1,0)) -> 1 | LS37: =E52+G55+G57 -> 6 | LT37: =G52+E55+E57 -> 5 | LU37: =LS37-LT37 -> 1 | LV37: =LN37 -> 4 | LW37: =LU37/10 -> 0.1 | LX37: =LS37/100 -> 0.06 | LY37: =SUM(LV37:LX37) -> 4.16 | LZ37: =IF(LY37=LY35,IF(G55>E55,0.001,0),0) -> 0 | MA37: =IF(LY37=LY36,IF(G57>E57,0.001,0),0) -> 0 | MB37: =IF(LY37=LY38,IF(E52>G52,0.001,0),0) -> 0 | MC37: =SUM(LY37:MB37) -> 4.16 | MD37: =RANK($MC$37,$MC$35:$MC$38,0) -> 3 | ME37: =IF(OR(AND(MD35=MD36,MD35=MD37,MD35=MD38),AND(MD37=MD35,MD37=MD36)),MD37+2,IF(OR(AND(MD37=MD36,MD37=MD38),MD37=MD35,MD37=MD36),MD37+1,MD37)) -> 3 | MF37: 3 | MG37: =MATCH(MF37,$ME$35:$ME$38,0) -> 3 | MH37: =INDEX($LM$35:$LM$38,MG37) -> Alemanha
A38: 44891 | B38: 0.41666667 | C38: Polônia | E38: 2 | F38: x | G38: 0 | I38: Arábia Saudita | J38: Cid. da Educ. | L38: ='Resultado Oficial'!MH19 -> Argentina | M38: =VLOOKUP(L38,'Resultado Oficial'!$LM$19:$LU$22,2,FALSE) -> 6 | N38: =VLOOKUP(L38,'Resultado Oficial'!$LM$19:$LU$22,3,FALSE) -> 3 | O38: =VLOOKUP(L38,'Resultado Oficial'!$LM$19:$LU$22,4,FALSE) -> 2 | P38: =VLOOKUP(L38,'Resultado Oficial'!$LM$19:$LU$22,5,FALSE) -> 0 | Q38: =VLOOKUP(L38,'Resultado Oficial'!$LM$19:$LU$22,6,FALSE) -> 1 | R38: =VLOOKUP(L38,'Resultado Oficial'!$LM$19:$LU$22,7,FALSE) -> 5 | S38: =VLOOKUP(L38,'Resultado Oficial'!$LM$19:$LU$22,8,FALSE) -> 2 | T38: =VLOOKUP(L38,'Resultado Oficial'!$LM$19:$LU$22,9,FALSE) -> 3 | V38: 1o Colocado | W38: =IF(SUM(N38:N41)<>12,"",L38) -> Argentina | LM38: Japão | LN38: =IF(OR(G52="",E52=""),0,IF(LO38=0,0,IF(G52>E52,3,IF(G52=E52,1,0)))+IF(OR(E54="",G54=""),0,IF(E54>G54,3,IF(E54=G54,1,0)))+IF(OR(E56="",G56=""),0,IF(E56>G56,3,IF(E56=G56,1,0)))) -> 6 | LO38: =IF(AND(E52<>"",G52<>""),1,0)+IF(AND(E54<>"",G54<>""),1,0)+IF(AND(E56<>"",G56<>""),1,0) -> 3 | LP38: =IF(OR(G52="",E52=""),0,IF(G52>E52,1,0))+IF(OR(E54="",G54=""),0,IF(E54>G54,1,0))+IF(OR(E56="",G56=""),0,IF(E56>G56,1,0)) -> 2 | LQ38: =IF(OR(G52="",E52=""),0,IF(G52=E52,1,0))+IF(OR(E54="",G54=""),0,IF(E54=G54,1,0))+IF(OR(E56="",G56=""),0,IF(E56=G56,1,0)) -> 0 | LR38: =IF(OR(G52="",E52=""),0,IF(G52<E52,1,0))+IF(OR(E54="",G54=""),0,IF(E54<G54,1,0))+IF(OR(E56="",G56=""),0,IF(E56<G56,1,0)) -> 1 | LS38: =G52+E54+E56 -> 4 | LT38: =E52+G54+G56 -> 3 | LU38: =LS38-LT38 -> 1 | LV38: =LN38 -> 6 | LW38: =LU38/10 -> 0.1 | LX38: =LS38/100 -> 0.04 | LY38: =SUM(LV38:LX38) -> 6.14 | LZ38: =IF(LY38=LY35,IF(E56>G56,0.001,0),0) -> 0 | MA38: =IF(LY38=LY36,IF(E54>G54,0.001,0),0) -> 0 | MB38: =IF(LY38=LY37,IF(G52>E52,0.001,0),0) -> 0 | MC38: =SUM(LY38:MB38) -> 6.14 | MD38: =RANK($MC$38,$MC$35:$MC$38,0) -> 1 | ME38: =IF(AND(MD35=MD36,MD35=MD37,MD35=MD38),MD38+3,IF(OR(AND(MD38=MD37,MD38=MD36),AND(MD38=MD36,MD38=MD35)),MD38+2,IF(OR(MD38=MD37,MD38=MD36,MD38=MD35),MD38+1,MD38))) -> 1 | MF38: 4 | MG38: =MATCH(MF38,$ME$35:$ME$38,0) -> 2 | MH38: =INDEX($LM$35:$LM$38,MG38) -> Costa Rica
A39: 44891 | B39: 0.66666667 | C39: Argentina | E39: 2 | F39: x | G39: 0 | I39: México | J39: Lusail | L39: ='Resultado Oficial'!MH20 -> Polônia | M39: =VLOOKUP(L39,'Resultado Oficial'!$LM$19:$LU$22,2,FALSE) -> 4 | N39: =VLOOKUP(L39,'Resultado Oficial'!$LM$19:$LU$22,3,FALSE) -> 3 | O39: =VLOOKUP(L39,'Resultado Oficial'!$LM$19:$LU$22,4,FALSE) -> 1 | P39: =VLOOKUP(L39,'Resultado Oficial'!$LM$19:$LU$22,5,FALSE) -> 1 | Q39: =VLOOKUP(L39,'Resultado Oficial'!$LM$19:$LU$22,6,FALSE) -> 1 | R39: =VLOOKUP(L39,'Resultado Oficial'!$LM$19:$LU$22,7,FALSE) -> 2 | S39: =VLOOKUP(L39,'Resultado Oficial'!$LM$19:$LU$22,8,FALSE) -> 2 | T39: =VLOOKUP(L39,'Resultado Oficial'!$LM$19:$LU$22,9,FALSE) -> 0 | V39: 2o Colocado | W39: =IF(SUM(N38:N41)<>12,"",L39) -> Polônia
A40: 44895 | B40: 0.66666667 | C40: Polônia | E40: 0 | F40: x | G40: 2 | I40: Argentina | J40: Estádio 974 | L40: ='Resultado Oficial'!MH21 -> México | M40: =VLOOKUP(L40,'Resultado Oficial'!$LM$19:$LU$22,2,FALSE) -> 4 | N40: =VLOOKUP(L40,'Resultado Oficial'!$LM$19:$LU$22,3,FALSE) -> 3 | O40: =VLOOKUP(L40,'Resultado Oficial'!$LM$19:$LU$22,4,FALSE) -> 1 | P40: =VLOOKUP(L40,'Resultado Oficial'!$LM$19:$LU$22,5,FALSE) -> 1 | Q40: =VLOOKUP(L40,'Resultado Oficial'!$LM$19:$LU$22,6,FALSE) -> 1 | R40: =VLOOKUP(L40,'Resultado Oficial'!$LM$19:$LU$22,7,FALSE) -> 2 | S40: =VLOOKUP(L40,'Resultado Oficial'!$LM$19:$LU$22,8,FALSE) -> 3 | T40: =VLOOKUP(L40,'Resultado Oficial'!$LM$19:$LU$22,9,FALSE) -> -1
A41: 44895 | B41: 0.66666667 | C41: Arábia Saudita | E41: 1 | F41: x | G41: 2 | I41: México | J41: Lusail | L41: ='Resultado Oficial'!MH22 -> Arábia Saudita | M41: =VLOOKUP(L41,'Resultado Oficial'!$LM$19:$LU$22,2,FALSE) -> 3 | N41: =VLOOKUP(L41,'Resultado Oficial'!$LM$19:$LU$22,3,FALSE) -> 3 | O41: =VLOOKUP(L41,'Resultado Oficial'!$LM$19:$LU$22,4,FALSE) -> 1 | P41: =VLOOKUP(L41,'Resultado Oficial'!$LM$19:$LU$22,5,FALSE) -> 0 | Q41: =VLOOKUP(L41,'Resultado Oficial'!$LM$19:$LU$22,6,FALSE) -> 2 | R41: =VLOOKUP(L41,'Resultado Oficial'!$LM$19:$LU$22,7,FALSE) -> 3 | S41: =VLOOKUP(L41,'Resultado Oficial'!$LM$19:$LU$22,8,FALSE) -> 5 | T41: =VLOOKUP(L41,'Resultado Oficial'!$LM$19:$LU$22,9,FALSE) -> -2 | LN41: Grupo F
LM42: Seleção | LN42: PT | LO42: J | LP42: V | LQ42: =IF(OR(E59="",G59=""),0,IF(E59=G59,1,0))+IF(OR(E61="",G61=""),0,IF(E61=G61,1,0))+IF(OR(G63="",E63=""),0,IF(G63=E63,1,0)) -> 0 | LR42: D | LS42: GP | LT42: GC | LU42: SG
A43: Primeira fase GRUPO D | LM43: Bélgica | LN43: =IF(OR(E61="",G61=""),0,IF(LO43=0,0,IF(E61>G61,3,IF(E61=G61,1,0)))+IF(OR(E62="",G62=""),0,IF(E62>G62,3,IF(E62=G62,1,0)))+IF(OR(G64="",E64=""),0,IF(G64>E64,3,IF(G64=E64,1,0)))) -> 4 | LO43: =IF(AND(E61<>"",G61<>""),1,0)+IF(AND(E62<>"",G62<>""),1,0)+IF(AND(E64<>"",G64<>""),1,0) -> 3 | LP43: =IF(OR(E61="",G61=""),0,IF(E61>G61,1,0))+IF(OR(E62="",G62=""),0,IF(E62>G62,1,0))+IF(OR(G64="",E64=""),0,IF(G64>E64,1,0)) -> 1 | LQ43: =IF(OR(E61="",G61=""),0,IF(E61=G61,1,0))+IF(OR(E62="",G62=""),0,IF(E62=G62,1,0))+IF(OR(G64="",E64=""),0,IF(G64=E64,1,0)) -> 1 | LR43: =IF(OR(E61="",G61=""),0,IF(E61<G61,1,0))+IF(OR(E62="",G62=""),0,IF(E62<G62,1,0))+IF(OR(G64="",E64=""),0,IF(G64<E64,1,0)) -> 1 | LS43: =E61+E62+G64 -> 1 | LT43: =G61+G62+E64 -> 2 | LU43: =LS43-LT43 -> -1 | LV43: =LN43 -> 4 | LW43: =LU43/10 -> -0.1 | LX43: =LS43/100 -> 0.01 | LY43: =SUM(LV43:LX43) -> 3.91 | LZ43: =IF(LY43=LY44,IF(E61>G61,0.001,0),0) -> 0 | MA43: =IF(LY43=LY45,IF(E62>G62,0.001,0),0) -> 0 | MB43: =IF(LY43=LY46,IF(G64>E64,0.001,0),0) -> 0 | MC43: =SUM(LY43:MB43) -> 3.91 | MD43: =RANK($MC$43,$MC$43:$MC$46,0) -> 3 | ME43: =MD43 -> 3 | MF43: 1 | MG43: =MATCH(MF43,$ME$43:$ME$46,0) -> 3 | MH43: =INDEX($LM$43:$LM$46,MG43) -> Marrocos
A44: 44887 | B44: 0.41666667 | C44: Dinamarca | E44: 0 | F44: x | G44: 0 | I44: Tunísia | J44: Cid. da Educ. | L44: Classificação do grupo D | LM44: Canadá | LN44: =IF(OR(G61="",E61=""),0,IF(LO44=0,0,IF(G61>E61,3,IF(G61=E61,1,0)))+IF(OR(G63="",E63=""),0,IF(G63>E63,3,IF(G63=E63,1,0)))+IF(OR(G65="",E65=""),0,IF(E65>G65,3,IF(E65=G65,1,0)))) -> 0 | LO44: =IF(AND(E61<>"",G61<>""),1,0)+IF(AND(E63<>"",G63<>""),1,0)+IF(AND(E65<>"",G65<>""),1,0) -> 3 | LP44: =IF(OR(G61="",E61=""),0,IF(G61>E61,1,0))+IF(OR(G63="",E63=""),0,IF(G63>E63,1,0))+IF(OR(E65="",G65=""),0,IF(E65>G65,1,0)) -> 0 | LQ44: =IF(OR(G61="",E61=""),0,IF(G61=E61,1,0))+IF(OR(G63="",E63=""),0,IF(G63=E63,1,0))+IF(OR(E65="",G65=""),0,IF(E65=G65,1,0)) -> 0 | LR44: =IF(OR(G61="",E61=""),0,IF(G61<E61,1,0))+IF(OR(G63="",E63=""),0,IF(G63<E63,1,0))+IF(OR(E65="",G65=""),0,IF(E65<G65,1,0)) -> 3 | LS44: =G61+G63+E65 -> 2 | LT44: =E61+E63+G65 -> 7 | LU44: =LS44-LT44 -> -5 | LV44: =LN44 -> 0 | LW44: =LU44/10 -> -0.5 | LX44: =LS44/100 -> 0.02 | LY44: =SUM(LV44:LX44) -> -0.48 | LZ44: =IF(LY44=LY43,IF(G61>E61,0.001,0),0) -> 0 | MA44: =IF(LY44=LY45,IF(E65>G65,0.001,0),0) -> 0 | MB44: =IF(LY44=LY46,IF(G63>E63,0.001,0),0) -> 0 | MC44: =SUM(LY44:MB44) -> -0.48 | MD44: =RANK($MC$44,$MC$43:$MC$46,0) -> 4 | ME44: =IF(OR(AND(MD43=MD44,MD43=MD45,MD43=MD46),AND(MD44=MD43,MD44=MD45),AND(MD44=MD43,MD44=MD46),MD44=MD43),MD44+1,MD44) -> 4 | MF44: 2 | MG44: =MATCH(MF44,$ME$43:$ME$46,0) -> 4 | MH44: =INDEX($LM$43:$LM$46,MG44) -> Croácia
...

Sheet Controle
A1: Posicao | B1: Nome | C1: Pontos | E1: Nome | F1: Pago | K1: Arrecadado | L1: =(COUNTA(F:F)-1)*100 -> 1000
A2: =IF(C2=C1,A1,ROW(C2)-1) -> 1 | B2: Lopes | C2: =Lopes!$L$7 -> 259 | D2: =IF(C2=C1,D1,ROW(C2)-1) -> 1 | E2: Marco | F2: 17/11
A3: =IF(C3=C2,A2,ROW(C3)-1) -> 2 | B3: Rodrigo | C3: =Rodrigo!$L$7 -> 215 | D3: =IF(C3=C2,D2,ROW(C3)-1) -> 2 | E3: Gogó | F3: 17/11
A4: =IF(C4=C3,A3,ROW(C4)-1) -> 3 | B4: Mothci | C4: =Mothci!$L$7 -> 209 | D4: =IF(C4=C3,D3,ROW(C4)-1) -> 3 | E4: Rodrigo | F4: 14/11
A5: =IF(C5=C4,A4,ROW(C5)-1) -> 3 | B5: Gogó | C5: ='Gogó'!$L$7 -> 209 | D5: =IF(C5=C4,D4,ROW(C5)-1) -> 3 | E5: Mothci | F5: 14/11 | K5: Premio 1o | L5: =M5*$L$1*0.01 -> 700 | M5: 70
A6: =IF(C6=C5,A5,ROW(C6)-1) -> 5 | B6: Danilo | C6: =Danilo!$L$7 -> 203 | D6: =IF(C6=C5,D5,ROW(C6)-1) -> 5 | E6: Bill | F6: 15/11 | G6: =ROW() -> 6
A7: =IF(C7=C6,A6,ROW(C7)-1) -> 6 | B7: Epocler | C7: =Epocler!$L$7 -> 191 | D7: =IF($C$2=$C$1,$A6,ROW($C$2)-1) -> 1 | E7: Leo | F7: 14/11 | K7: Premio 3o | L7: =M7*$L$1*0.01 -> 100 | M7: 10
A8: =IF(C8=C7,A7,ROW(C8)-1) -> 7 | B8: Zé | C8: ='Zé Augusto'!$L$7 -> 178 | D8: =IF(C8=C7,D7,ROW(C8)-1) -> 7 | E8: Epocler | F8: 14/11
A9: =IF(C9=C8,A8,ROW(C9)-1) -> 8 | B9: Bill | C9: =Bill!$L$7 -> 177 | D9: =IF(C9=C8,D8,ROW(C9)-1) -> 8 | E9: Zé | F9: 15/11
A10: =IF(C10=C9,A9,ROW(C10)-1) -> 9 | B10: Leo | C10: =Leo!$L$7 -> 171 | D10: =IF(C10=C9,D9,ROW(C10)-1) -> 9 | E10: Lopes | F10: 14/11 | K10: Premio 2o | L10: =M10*$L$1*0.01 -> 200 | M10: 20
A11: =IF(C11=C10,A10,ROW(C11)-1) -> 10 | B11: Marco | C11: =Marco!$L$7 -> 144 | D11: =IF(C11=C10,D10,ROW(C11)-1) -> 10 | E11: Danilo | F11: 17/11

Sheet Nome Palpiteiro
LN1: Grupo A
LM2: Seleção | LN2: PT | LO2: J | LP2: V | LQ2: E | LR2: D | LS2: GP | LT2: GC | LU2: SG
LM3: Catar | LN3: =IF(OR(E20="",G20=""),0,IF(LO3=0,0,IF(E20>G20,3,IF(E20=G20,1,0)))+IF(OR(E22="",G22=""),0,IF(E22>G22,3,IF(E22=G22,1,0)))+IF(OR(G25="",E25=""),0,IF(G25>E25,3,IF(G25=E25,1,0)))) -> 0 | LO3: =IF(AND(E20<>"",G20<>""),1,0)+IF(AND(E22<>"",G22<>""),1,0)+IF(AND(E25<>"",G25<>""),1,0) -> 0 | LP3: =IF(OR(E20="",G20=""),0,IF(E20>G20,1,0))+IF(OR(E22="",G22=""),0,IF(E22>G22,1,0))+IF(OR(G25="",E25=""),0,IF(G25>E25,1,0)) -> 0 | LQ3: =IF(OR(E20="",G20=""),0,IF(E20=G20,1,0))+IF(OR(E22="",G22=""),0,IF(E22=G22,1,0))+IF(OR(G25="",E25=""),0,IF(G25=E25,1,0)) -> 0 | LR3: =IF(OR(E20="",G20=""),0,IF(E20<G20,1,0))+IF(OR(E22="",G22=""),0,IF(E22<G22,1,0))+IF(OR(G25="",E25=""),0,IF(G25<E25,1,0)) -> 0 | LS3: =E20+E22+G25 -> 0 | LT3: =G20+G22+E25 -> 0 | LU3: =LS3-LT3 -> 0 | LV3: =LN3 -> 0 | LW3: =LU3/10 -> 0 | LX3: =LS3/100 -> 0 | LY3: =SUM(LV3:LX3) -> 0 | LZ3: =IF(LY3=LY4,IF(E20>G20,0.001,0),0) -> 0 | MA3: =IF(LY3=LY5,IF(E22>G22,0.001,0),0) -> 0 | MB3: =IF(LY3=LY6,IF(G25>E25,0.001,0),0) -> 0 | MC3: =SUM(LY3:MB3) -> 0 | MD3: =RANK(MC3,$MC$3:$MC$6,0) -> 1 | ME3: =MD3 -> 1 | MF3: 1 | MG3: =MATCH(MF3,$ME$3:$ME$6,0) -> 1 | MH3: =INDEX($LM$3:$LM$6,MG3) -> Catar
A4: Bolão Copa 2022 - Câmara dos Lordes | LM4: Equador | LN4: =IF(OR(G20="",E20=""),0,IF(LO4=0,0,IF(G20>E20,3,IF(G20=E20,1,0)))+IF(OR(G23="",E23=""),0,IF(G23>E23,3,IF(G23=E23,1,0)))+IF(OR(G24="",E24=""),0,IF(E24>G24,3,IF(E24=G24,1,0)))) -> 0 | LO4: =IF(AND(E20<>"",G20<>""),1,0)+IF(AND(E23<>"",G23<>""),1,0)+IF(AND(E25<>"",G25<>""),1,0) -> 0 | LP4: =IF(OR(G20="",E20=""),0,IF(G20>E20,1,0))+IF(OR(G23="",E23=""),0,IF(G23>E23,1,0))+IF(OR(E25="",G25=""),0,IF(E25>G25,1,0)) -> 0 | LQ4: =IF(OR(G20="",E20=""),0,IF(G20=E20,1,0))+IF(OR(G23="",E23=""),0,IF(G23=E23,1,0))+IF(OR(E25="",G25=""),0,IF(E25=G25,1,0)) -> 0 | LR4: =IF(OR(G20="",E20=""),0,IF(G20<E20,1,0))+IF(OR(G23="",E23=""),0,IF(G23<E23,1,0))+IF(OR(E25="",G25=""),0,IF(E25<G25,1,0)) -> 0 | LS4: =G20+G23+E25 -> 0 | LT4: =E20+E23+G25 -> 0 | LU4: =LS4-LT4 -> 0 | LV4: =LN4 -> 0 | LW4: =LU4/10 -> 0 | LX4: =LS4/100 -> 0 | LY4: =SUM(LV4:LX4) -> 0 | LZ4: =IF(LY4=LY3,IF(G20>E20,0.001,0),0) -> 0 | MA4: =IF(LY4=LY5,IF(E24>G24,0.001,0),0) -> 0 | MB4: =IF(LY4=LY6,IF(G23>E23,0.001,0),0) -> 0 | MC4: =SUM(LY4:MB4) -> 0 | MD4: =RANK(MC4,$MC$3:$MC$6,0) -> 1 | ME4: =IF(OR(AND(MD3=MD4,MD3=MD5,MD3=MD6),AND(MD4=MD3,MD4=MD5),AND(MD4=MD3,MD4=MD6),MD4=MD3),MD4+1,MD4) -> 2 | MF4: 2 | MG4: =MATCH(MF4,$ME$3:$ME$6,0) -> 2 | MH4: =INDEX($LM$3:$LM$6,MG4) -> Equador
A5: Preencher as células em amarelo | LM5: Senegal | LN5: =IF(OR(E21="",G21=""),0,IF(LO5=0,0,IF(E21>G21,3,IF(E21=G21,1,0)))+IF(OR(G22="",E22=""),0,IF(G22>E22,3,IF(G22=E22,1,0)))+IF(OR(G24="",E24=""),0,IF(G24>E24,3,IF(E24=G24,1,0)))) -> 0 | LO5: =IF(AND(E21<>"",G21<>""),1,0)+IF(AND(E22<>"",G22<>""),1,0)+IF(AND(E24<>"",G24<>""),1,0) -> 0 | LP5: =IF(OR(E21="",G21=""),0,IF(E21>G21,1,0))+IF(OR(G22="",E22=""),0,IF(G22>E22,1,0))+IF(OR(G24="",E24=""),0,IF(G24>E24,1,0)) -> 0 | LQ5: =IF(OR(E21="",G21=""),0,IF(E21=G21,1,0))+IF(OR(G22="",E22=""),0,IF(G22=E22,1,0))+IF(OR(G24="",E24=""),0,IF(G24=E24,1,0)) -> 0 | LR5: =IF(OR(E21="",G21=""),0,IF(E21<G21,1,0))+IF(OR(G22="",E22=""),0,IF(G22<E22,1,0))+IF(OR(G24="",E24=""),0,IF(G24<E24,1,0)) -> 0 | LS5: =E21+G22+G24 -> 0 | LT5: =G21+E22+E24 -> 0 | LU5: =LS5-LT5 -> 0 | LV5: =LN5 -> 0 | LW5: =LU5/10 -> 0 | LX5: =LS5/100 -> 0 | LY5: =SUM(LV5:LX5) -> 0 | LZ5: =IF(LY5=LY3,IF(G22>E22,0.001,0),0) -> 0 | MA5: =IF(LY5=LY4,IF(G24>E24,0.001,0),0) -> 0 | MB5: =IF(LY5=LY6,IF(E21>G21,0.001,0),0) -> 0 | MC5: =SUM(LY5:MB5) -> 0 | MD5: =RANK(MC5,$MC$3:$MC$6,0) -> 1 | ME5: =IF(OR(AND(MD3=MD4,MD3=MD5,MD3=MD6),AND(MD5=MD3,MD5=MD4)),MD5+2,IF(OR(AND(MD5=MD4,MD5=MD6),MD5=MD3,MD5=MD4),MD5+1,MD5)) -> 3 | MF5: 3 | MG5: =MATCH(MF5,$ME$3:$ME$6,0) -> 3 | MH5: =INDEX($LM$3:$LM$6,MG5) -> Senegal
A6: Nome do Palpiteiro: | L6: ="Total de Pontos até " & TEXT(NOW(),"dd/mm/aaaa") -> Total de Pontos até 24/04/Friday | LM6: Holanda | LN6: =IF(OR(G21="",E21=""),0,IF(LO6=0,0,IF(G21>E21,3,IF(G21=E21,1,0)))+IF(OR(E23="",G23=""),0,IF(E23>G23,3,IF(E23=G23,1,0)))+IF(OR(E25="",G25=""),0,IF(E25>G25,3,IF(E25=G25,1,0)))) -> 0 | LO6: =IF(AND(E21<>"",G21<>""),1,0)+IF(AND(E23<>"",G23<>""),1,0)+IF(AND(E25<>"",G25<>""),1,0) -> 0 | LP6: =IF(OR(G21="",E21=""),0,IF(G21>E21,1,0))+IF(OR(E23="",G23=""),0,IF(E23>G23,1,0))+IF(OR(E25="",G25=""),0,IF(E25>G25,1,0)) -> 0 | LQ6: =IF(OR(G21="",E21=""),0,IF(G21=E21,1,0))+IF(OR(E23="",G23=""),0,IF(E23=G23,1,0))+IF(OR(E25="",G25=""),0,IF(E25=G25,1,0)) -> 0 | LR6: =IF(OR(G21="",E21=""),0,IF(G21<E21,1,0))+IF(OR(E23="",G23=""),0,IF(E23<G23,1,0))+IF(OR(E25="",G25=""),0,IF(E25<G25,1,0)) -> 0 | LS6: =G21+E23+E25 -> 0 | LT6: =E21+G23+G25 -> 0 | LU6: =LS6-LT6 -> 0 | LV6: =LN6 -> 0 | LW6: =LU6/10 -> 0 | LX6: =LS6/100 -> 0 | LY6: =SUM(LV6:LX6) -> 0 | LZ6: =IF(LY6=LY3,IF(E25>G25,0.001,0),0) -> 0 | MA6: =IF(LY6=LY4,IF(E23>G23,0.001,0),0) -> 0 | MB6: =IF(LY6=LY5,IF(G21>E21,0.001,0),0) -> 0 | MC6: =SUM(LY6:MB6) -> 0 | MD6: =RANK(MC6,$MC$3:$MC$6,0) -> 1 | ME6: =IF(AND(MD3=MD4,MD3=MD5,MD3=MD6),MD6+3,IF(OR(AND(MD6=MD5,MD6=MD4),AND(MD6=MD4,MD6=MD3)),MD6+2,IF(OR(MD6=MD5,MD6=MD4,MD6=MD3),MD6+1,MD6))) -> 4 | MF6: 4 | MG6: =MATCH(MF6,$ME$3:$ME$6,0) -> 4 | MH6: =INDEX($LM$3:$LM$6,MG6) -> Holanda
A7: E-mail do Palpiteiro: | L7: =SUM(Z18,X22:X23,X30:X31,X38:X39,X46:X47,X54:X55,X62:X63,X70:X71,X78:X79,L9:L14) -> 0
A9: Artilheiro da Copa: | L9: =(IF(OR(D9="",'Resultado Oficial'!D117=""),"",IF(D9='Resultado Oficial'!D117,40,0))) | LN9: Grupo B
LM10: Seleção | LN10: PT | LO10: J | LP10: V | LQ10: E | LR10: D | LS10: GP | LT10: GC | LU10: SG
A11: Campeão: | L11: =IF(OR(D11="",'Resultado Oficial'!D111=""),"",IF(D11='Resultado Oficial'!D111,40,IF(D11='Resultado Oficial'!D112,20,IF(D11='Resultado Oficial'!D113,20,IF('Nome Palpiteiro'!D11='Resultado Oficial'!D114,20,0))))) | LM11: Inglaterra | LN11: =IF(OR(E28="",G28=""),0,IF(LO11=0,0,IF(E28>G28,3,IF(E28=G28,1,0)))+IF(OR(E31="",G31=""),0,IF(E31>G31,3,IF(E31=G31,1,0)))+IF(OR(G32="",E32=""),0,IF(G32>E32,3,IF(G32=E32,1,0)))) -> 0 | LO11: =IF(AND(E28<>"",G28<>""),1,0)+IF(AND(E31<>"",G31<>""),1,0)+IF(AND(E32<>"",G32<>""),1,0) -> 0 | LP11: =IF(OR(E28="",G28=""),0,IF(E28>G28,1,0))+IF(OR(E31="",G31=""),0,IF(E31>G31,1,0))+IF(OR(G32="",E32=""),0,IF(G32>E32,1,0)) -> 0 | LQ11: =IF(OR(E28="",G28=""),0,IF(E28=G28,1,0))+IF(OR(E31="",G31=""),0,IF(E31=G31,1,0))+IF(OR(G32="",E32=""),0,IF(G32=E32,1,0)) -> 0 | LR11: =IF(OR(E28="",G28=""),0,IF(E28<G28,1,0))+IF(OR(E31="",G31=""),0,IF(E31<G31,1,0))+IF(OR(G32="",E32=""),0,IF(G32<E32,1,0)) -> 0 | LS11: =E28+E31+G32 -> 0 | LT11: =G28+G31+E32 -> 0 | LU11: =LS11-LT11 -> 0 | LV11: =LN11 -> 0 | LW11: =LU11/10 -> 0 | LX11: =LS11/100 -> 0 | LY11: =SUM(LV11:LX11) -> 0 | LZ11: =IF(LY11=LY12,IF(E28>G28,0.001,0),0) -> 0 | MA11: =IF(LY11=LY13,IF(E31>G31,0.001,0),0) -> 0 | MB11: =IF(LY11=LY14,IF(G32>E32,0.001,0),0) -> 0 | MC11: =SUM(LY11:MB11) -> 0 | MD11: =RANK($MC$11,$MC$11:$MC$14,0) -> 1 | ME11: =MD11 -> 1 | MF11: 1 | MG11: =MATCH(MF11,$ME$11:$ME$14,0) -> 1 | MH11: =INDEX($LM$11:$LM$14,MG11) -> Inglaterra
A12: Vice-campeão: | L12: =IF(OR(D12="",'Resultado Oficial'!D112=""),"",IF(D12='Resultado Oficial'!D112,35,IF(D12='Resultado Oficial'!D111,20,IF(D12='Resultado Oficial'!D113,20,IF('Nome Palpiteiro'!D12='Resultado Oficial'!D114,20,0))))) | LM12: Irã | LN12: =IF(OR(G28="",E28=""),0,IF(LO12=0,0,IF(G28>E28,3,IF(G28=E28,1,0)))+IF(OR(G30="",E30=""),0,IF(G30>E30,3,IF(G30=E30,1,0)))+IF(OR(G33="",E33=""),0,IF(E33>G33,3,IF(E33=G33,1,0)))) -> 0 | LO12: =IF(AND(E28<>"",G28<>""),1,0)+IF(AND(E30<>"",G30<>""),1,0)+IF(AND(E33<>"",G33<>""),1,0) -> 0 | LP12: =IF(OR(G28="",E28=""),0,IF(G28>E28,1,0))+IF(OR(G30="",E30=""),0,IF(G30>E30,1,0))+IF(OR(E33="",G33=""),0,IF(E33>G33,1,0)) -> 0 | LQ12: =IF(OR(G28="",E28=""),0,IF(G28=E28,1,0))+IF(OR(G30="",E30=""),0,IF(G30=E30,1,0))+IF(OR(E33="",G33=""),0,IF(E33=G33,1,0)) -> 0 | LR12: =IF(OR(G28="",E28=""),0,IF(G28<E28,1,0))+IF(OR(G30="",E30=""),0,IF(G30<E30,1,0))+IF(OR(E33="",G33=""),0,IF(E33<G33,1,0)) -> 0 | LS12: =G28+G30+E33 -> 0 | LT12: =E28+E30+G33 -> 0 | LU12: =LS12-LT12 -> 0 | LV12: =LN12 -> 0 | LW12: =LU12/10 -> 0 | LX12: =LS12/100 -> 0 | LY12: =SUM(LV12:LX12) -> 0 | LZ12: =IF(LY12=LY11,IF(G28>E28,0.001,0),0) -> 0 | MA12: =IF(LY12=LY13,IF(E33>G33,0.001,0),0) -> 0 | MB12: =IF(LY12=LY14,IF(G30>E30,0.001,0),0) -> 0 | MC12: =SUM(LY12:MB12) -> 0 | MD12: =RANK($MC$12,$MC$11:$MC$14,0) -> 1 | ME12: =IF(OR(AND(MD11=MD12,MD11=MD13,MD11=MD14),AND(MD12=MD11,MD12=MD13),AND(MD12=MD11,MD12=MD14),MD12=MD11),MD12+1,MD12) -> 2 | MF12: 2 | MG12: =MATCH(MF12,$ME$11:$ME$14,0) -> 2 | MH12: =INDEX($LM$11:$LM$14,MG12) -> Irã
A13: 3º Lugar: | L13: =IF(OR(D13="",'Resultado Oficial'!D113=""),"",IF(D13='Resultado Oficial'!D113,30,IF(D13='Resultado Oficial'!D111,20,IF(D13='Resultado Oficial'!D112,20,IF('Nome Palpiteiro'!D13='Resultado Oficial'!D114,20,0))))) | LM13: Estados Unidos | LN13: =IF(OR(E29="",G29=""),0,IF(LO13=0,0,IF(E29>G29,3,IF(E29=G29,1,0)))+IF(OR(G31="",E31=""),0,IF(G31>E31,3,IF(G31=E31,1,0)))+IF(OR(G33="",E33=""),0,IF(G33>E33,3,IF(E33=G33,1,0)))) -> 0 | LO13: =IF(AND(E29<>"",G29<>""),1,0)+IF(AND(E31<>"",G31<>""),1,0)+IF(AND(E33<>"",G33<>""),1,0) -> 0 | LP13: =IF(OR(E29="",G29=""),0,IF(E29>G29,1,0))+IF(OR(G31="",E31=""),0,IF(G31>E31,1,0))+IF(OR(G33="",E33=""),0,IF(G33>E33,1,0)) -> 0 | LQ13: =IF(OR(E29="",G29=""),0,IF(E29=G29,1,0))+IF(OR(G31="",E31=""),0,IF(G31=E31,1,0))+IF(OR(G33="",E33=""),0,IF(G33=E33,1,0)) -> 0 | LR13: =IF(OR(E29="",G29=""),0,IF(E29<G29,1,0))+IF(OR(G31="",E31=""),0,IF(G31<E31,1,0))+IF(OR(G33="",E33=""),0,IF(G33<E33,1,0)) -> 0 | LS13: =E29+G31+G33 -> 0 | LT13: =G29+E31+E33 -> 0 | LU13: =LS13-LT13 -> 0 | LV13: =LN13 -> 0 | LW13: =LU13/10 -> 0 | LX13: =LS13/100 -> 0 | LY13: =SUM(LV13:LX13) -> 0 | LZ13: =IF(LY13=LY11,IF(G31>E31,0.001,0),0) -> 0 | MA13: =IF(LY13=LY12,IF(G33>E33,0.001,0),0) -> 0 | MB13: =IF(LY13=LY14,IF(E29>G29,0.001,0),0) -> 0 | MC13: =SUM(LY13:MB13) -> 0 | MD13: =RANK($MC$13,$MC$11:$MC$14,0) -> 1 | ME13: =IF(OR(AND(MD11=MD12,MD11=MD13,MD11=MD14),AND(MD13=MD11,MD13=MD12)),MD13+2,IF(OR(AND(MD13=MD12,MD13=MD14),MD13=MD11,MD13=MD12),MD13+1,MD13)) -> 3 | MF13: 3 | MG13: =MATCH(MF13,$ME$11:$ME$14,0) -> 3 | MH13: =INDEX($LM$11:$LM$14,MG13) -> Estados Unidos
A14: 4º Lugar: | L14: =IF(OR(D14="",'Resultado Oficial'!D114=""),"",IF(D14='Resultado Oficial'!D114,25,IF(D14='Resultado Oficial'!D111,20,IF(D14='Resultado Oficial'!D112,20,IF('Nome Palpiteiro'!D14='Resultado Oficial'!D113,20,0))))) | LM14: País de Gales | LN14: =IF(OR(G29="",E29=""),0,IF(LO14=0,0,IF(G29>E29,3,IF(G29=E29,1,0)))+IF(OR(E30="",G30=""),0,IF(E30>G30,3,IF(E30=G30,1,0)))+IF(OR(E32="",G32=""),0,IF(E32>G32,3,IF(E32=G32,1,0)))) -> 0 | LO14: =IF(AND(E29<>"",G29<>""),1,0)+IF(AND(E30<>"",G30<>""),1,0)+IF(AND(E32<>"",G32<>""),1,0) -> 0 | LP14: =IF(OR(G29="",E29=""),0,IF(G29>E29,1,0))+IF(OR(E30="",G30=""),0,IF(E30>G30,1,0))+IF(OR(E32="",G32=""),0,IF(E32>G32,1,0)) -> 0 | LQ14: =IF(OR(G29="",E29=""),0,IF(G29=E29,1,0))+IF(OR(E30="",G30=""),0,IF(E30=G30,1,0))+IF(OR(E32="",G32=""),0,IF(E32=G32,1,0)) -> 0 | LR14: =IF(OR(G29="",E29=""),0,IF(G29<E29,1,0))+IF(OR(E30="",G30=""),0,IF(E30<G30,1,0))+IF(OR(E32="",G32=""),0,IF(E32<G32,1,0)) -> 0 | LS14: =G29+E30+E32 -> 0 | LT14: =E29+G30+G32 -> 0 | LU14: =LS14-LT14 -> 0 | LV14: =LN14 -> 0 | LW14: =LU14/10 -> 0 | LX14: =LS14/100 -> 0 | LY14: =SUM(LV14:LX14) -> 0 | LZ14: =IF(LY14=LY11,IF(E32>G32,0.001,0),0) -> 0 | MA14: =IF(LY14=LY12,IF(E30>G30,0.001,0),0) -> 0 | MB14: =IF(LY14=LY13,IF(G29>E29,0.001,0),0) -> 0 | MC14: =SUM(LY14:MB14) -> 0 | MD14: =RANK($MC$14,$MC$11:$MC$14,0) -> 1 | ME14: =IF(AND(MD11=MD12,MD11=MD13,MD11=MD14),MD14+3,IF(OR(AND(MD14=MD13,MD14=MD12),AND(MD14=MD12,MD14=MD11)),MD14+2,IF(OR(MD14=MD13,MD14=MD12,MD14=MD11),MD14+1,MD14))) -> 4 | MF14: 4 | MG14: =MATCH(MF14,$ME$11:$ME$14,0) -> 4 | MH14: =INDEX($LM$11:$LM$14,MG14) -> País de Gales
A17: 1a Fase | Z17: Pontos Jogos | LN17: Grupo C
Z18: =SUM(Z20:Z81) -> 0 | LM18: Seleção | LN18: PT | LO18: J | LP18: V | LQ18: E | LR18: D | LS18: GP | LT18: GC | LU18: SG
A19: Primeira fase GRUPO A | LM19: Argentina | LN19: =IF(OR(E36="",G36=""),0,IF(LO19=0,0,IF(E36>G36,3,IF(E36=G36,1,0)))+IF(OR(E39="",G39=""),0,IF(E39>G39,3,IF(E39=G39,1,0)))+IF(OR(G40="",E40=""),0,IF(G40>E40,3,IF(G40=E40,1,0)))) -> 0 | LO19: =IF(AND(E36<>"",G36<>""),1,0)+IF(AND(E39<>"",G39<>""),1,0)+IF(AND(E40<>"",G40<>""),1,0) -> 0 | LP19: =IF(OR(E36="",G36=""),0,IF(E36>G36,1,0))+IF(OR(E39="",G39=""),0,IF(E39>G39,1,0))+IF(OR(G40="",E40=""),0,IF(G40>E40,1,0)) -> 0 | LQ19: =IF(OR(E36="",G36=""),0,IF(E36=G36,1,0))+IF(OR(E39="",G39=""),0,IF(E39=G39,1,0))+IF(OR(G40="",E40=""),0,IF(G40=E40,1,0)) -> 0 | LR19: =IF(OR(E36="",G36=""),0,IF(E36<G36,1,0))+IF(OR(E39="",G39=""),0,IF(E39<G39,1,0))+IF(OR(G40="",E40=""),0,IF(G40<E40,1,0)) -> 0 | LS19: =E36+E39+G40 -> 0 | LT19: =G36+G39+E40 -> 0 | LU19: =LS19-LT19 -> 0 | LV19: =LN19 -> 0 | LW19: =LU19/10 -> 0 | LX19: =LS19/100 -> 0 | LY19: =SUM(LV19:LX19) -> 0 | LZ19: =IF(LY19=LY20,IF(E36>G36,0.001,0),0) -> 0 | MA19: =IF(LY19=LY21,IF(E39>G39,0.001,0),0) -> 0 | MB19: =IF(LY19=LY22,IF(G40>E40,0.001,0),0) -> 0 | MC19: =SUM(LY19:MB19) -> 0 | MD19: =RANK($MC$19,$MC$19:$MC$22,0) -> 1 | ME19: =MD19 -> 1 | MF19: 1 | MG19: =MATCH(MF19,$ME$19:$ME$22,0) -> 1 | MH19: =INDEX($LM$19:$LM$22,MG19) -> Argentina
A20: 44885 | B20: 0.54166667 | C20: Catar | F20: x | I20: Equador | J20: Al Bayt | L20: Classificação do grupo A | Z20: =IF(OR(E20="",G20="",'Resultado Oficial'!E20="",'Resultado Oficial'!G20=""),"", IF(AND(E20='Resultado Oficial'!E20,G20='Resultado Oficial'!G20),10, IF(AND(E20=G20,'Resultado Oficial'!E20='Resultado Oficial'!G20,ABS((E20-'Resultado Oficial'!E20))=1),6, IF(AND(E20>G20,'Resultado Oficial'!E20>'Resultado Oficial'!G20,((E20-'Resultado Oficial'!E20)=(G20-'Resultado Oficial'!G20))),6, IF(AND(E20<G20,'Resultado Oficial'!E20<'Resultado Oficial'!G20,(('Resultado Oficial'!E20-E20)=('Resultado Oficial'!G20-G20))),6, IF(AND(E20>G20,'Resultado Oficial'!E20>'Resultado Oficial'!G20),3, IF(AND(E20=G20,'Resultado Oficial'!E20='Resultado Oficial'!G20),3, IF(AND(E20<G20,'Resultado Oficial'!E20<'Resultado Oficial'!G20),3,0)))))))) | LM20: Arábia Saudita | LN20: =IF(OR(G36="",E36=""),0,IF(LO20=0,0,IF(G36>E36,3,IF(G36=E36,1,0)))+IF(OR(G38="",E38=""),0,IF(G38>E38,3,IF(G38=E38,1,0)))+IF(OR(G41="",E41=""),0,IF(E41>G41,3,IF(E41=G41,1,0)))) -> 0 | LO20: =IF(AND(E36<>"",G36<>""),1,0)+IF(AND(E38<>"",G38<>""),1,0)+IF(AND(E41<>"",G41<>""),1,0) -> 0 | LP20: =IF(OR(G36="",E36=""),0,IF(G36>E36,1,0))+IF(OR(G38="",E38=""),0,IF(G38>E38,1,0))+IF(OR(E41="",G41=""),0,IF(E41>G41,1,0)) -> 0 | LQ20: =IF(OR(G36="",E36=""),0,IF(G36=E36,1,0))+IF(OR(G38="",E38=""),0,IF(G38=E38,1,0))+IF(OR(E41="",G41=""),0,IF(E41=G41,1,0)) -> 0 | LR20: =IF(OR(G36="",E36=""),0,IF(G36<E36,1,0))+IF(OR(G38="",E38=""),0,IF(G38<E38,1,0))+IF(OR(E41="",G41=""),0,IF(E41<G41,1,0)) -> 0 | LS20: =G36+G38+E41 -> 0 | LT20: =E36+E38+G41 -> 0 | LU20: =LS20-LT20 -> 0 | LV20: =LN20 -> 0 | LW20: =LU20/10 -> 0 | LX20: =LS20/100 -> 0 | LY20: =SUM(LV20:LX20) -> 0 | LZ20: =IF(LY20=LY19,IF(G36>E36,0.001,0),0) -> 0 | MA20: =IF(LY20=LY21,IF(E41>G41,0.001,0),0) -> 0 | MB20: =IF(LY20=LY22,IF(G38>E38,0.001,0),0) -> 0 | MC20: =SUM(LY20:MB20) -> 0 | MD20: =RANK($MC$20,$MC$19:$MC$22,0) -> 1 | ME20: =IF(OR(AND(MD19=MD20,MD19=MD21,MD19=MD22),AND(MD20=MD19,MD20=MD21),AND(MD20=MD19,MD20=MD22),MD20=MD19),MD20+1,MD20) -> 2 | MF20: 2 | MG20: =MATCH(MF20,$ME$19:$ME$22,0) -> 2 | MH20: =INDEX($LM$19:$LM$22,MG20) -> Arábia Saudita
